Workbook

Sheet Sheet1
A1: =+INDEX('EMP NAMES'!D:D,Sheet1!U5) -> 0 | I1: =+IF(M25=M28,"OLD","NEW") -> OLD | U1: SR | V1: 115BAC Section Applicable (New Tax Regime) | W1: PAN NO. | X1: NAME OF EMPLOYEE | Y1: Salary as per provisions contained in section 17(1) | Z1: Value of perquisites [section 17(2)] (as per FormNo.12BA, wherever applicable) | AA1: Reported total amount of salary received from other employer(s) | AB1: GROSS SALARY | AC1: STD DED | AD1: PT | AE1: HRA | AF1: OTHER ALLOWANCES 10 | AG1: NET | AH1: HSG. INT | AI1: OTHER INCOME | AJ1: NET | AK1: 80C INVESTMENT | AL1: 80C ELIGIBLE | AM1: 80CCD1 GROSS | AN1: 80CCD1 ELIGIBLE | AO1: 80CCD1(B) ELIGIBLE | AP1: 80CCD2 ELIGIBLE | AQ1: 80D | AR1: 80E | AS1: 80G | AT1: OTHERS | AU1: TOTAL ELIGIBLE SAVING | AV1: TAXABLE | AW1: TAX | AX1: REBATE | AY1: CESS | AZ1: RELIEF | BA1: TOTAL TAX | BB1: TDS-CURRENT | BC1: TDS-PREV. | BD1: TOTAL | BE1: R/P
G2: =IFERROR(INDEX('EMP NAMES'!E:E,Sheet1!U5),"PAN") -> PAN
N3: M
A4: SR. | B4: MONTH | C4: BASIC | D4: DA | E4: H. R. A. | F4: TA/SDA/CLA/RA/ETC | G4: WA | H4: DCPS Employer | I4: Basic Arr. / 7th Pay DCPS/NPS Arr | J4: Total Emolument | K4: PT | L4: GPF/DCPS Employee | M4: GIS | N4: LIC | O4: HBA HOUSE | P4: OTHER | Q4: NET | R4: I. TAX | S4: GROSS TOTAL ERROR | U4: SR | V4: 115BAC Section Applicable (New Tax Regime) | W4: PAN NO. | X4: NAME OF EMPLOYEE | Y4: Salary as per provisions contained in section 17(1) | Z4: Value of perquisites [section 17(2)] (as per FormNo.12BA, wherever applicable) | AA4: Reported total amount of salary received from other employer(s) | AB4: GROSS SALARY | AC4: STD DED | AD4: PT | AE4: HRA | AF4: OTHER ALLOWANCES 10 | AG4: NET | AH4: HSG. INT | AI4: OTHER INCOME | AJ4: NET | AK4: 80C INVESTMENT | AL4: 80C ELIGIBLE | AM4: 80CCD1 GROSS | AN4: 80CCD1 ELIGIBLE | AO4: 80CCD1(B) ELIGIBLE | AP4: 80CCD2 ELIGIBLE | AQ4: 80D | AR4: 80E | AS4: 80G | AT4: OTHERS | AU4: TOTAL ELIGIBLE SAVING | AV4: TAXABLE | AW4: TAX | AX4: REBATE | AY4: CESS | AZ4: RELIEF | BA4: TOTAL TAX | BB4: TDS-CURRENT | BC4: TDS-PREV. | BD4: TOTAL | BE4: R/P
A5: 1 | B5: 44256 | C5: =IFERROR(SUM(SUMIF(OFFSET('MAR-21'!$A$1,MATCH(Sheet1!A1,'MAR-21'!$A:$A,0),0,22,1),{"BA*C","BASIC??"},OFFSET('MAR-21'!$A$1,MATCH(Sheet1!A1,'MAR-21'!$A:$A,0),1,22,1))),0) -> 0 | D5: =IFERROR(SUM(SUMIF(OFFSET('MAR-21'!$A$1,MATCH(Sheet1!A1,'MAR-21'!$A:$A,0),0,22,1),{"DA*C","D. *"},OFFSET('MAR-21'!$A$1,MATCH(Sheet1!A1,'MAR-21'!$A:$A,0),1,22,1))),0) -> 0 | E5: =IFERROR(SUM(SUMIF(OFFSET('MAR-21'!$A$1,MATCH(Sheet1!A1,'MAR-21'!$A:$A,0),0,22,1),{"H. R. A."},OFFSET('MAR-21'!$A$1,MATCH(Sheet1!A1,'MAR-21'!$A:$A,0),1,22,1))),0) -> 0 | F5: {=IFERROR(SUM(SUMIF(OFFSET('MAR-21'!$A$1,MATCH(Sheet1!A1,'MAR-21'!$A:$A,0),0,22,1),{"SP*AY*","S D A*","O.A.*","CLA (5th Pay)*","REF. Allow*","Trans.Allw.*","LF*","P. O.*","ARM*","Conv.A*","Otr.Allow*","Trans_Arrear*","BMIA*","Incentives*","Fit Allow*","KMA","NON-*","U.*","ME*A","PG*","Per.Tra"},OFFSET('MAR-21'!$A$1,MATCH(Sheet1!A1,'MAR-21'!$A:$A,0),1,22,1))),0)} -> 0 | G5: =IFERROR(SUM(SUMIF(OFFSET('MAR-21'!$A$1,MATCH(Sheet1!A1,'MAR-21'!$A:$A,0),0,22,1),{"WA"},OFFSET('MAR-21'!$A$1,MATCH(Sheet1!A1,'MAR-21'!$A:$A,0),1,22,1))),0) -> 0 | H5: =IFERROR(SUM(SUMIF(OFFSET('MAR-21'!$A$1,MATCH(Sheet1!A1,'MAR-21'!$A:$A,0),0,22,1),{"DCPS","GROSS_ADJUST"},OFFSET('MAR-21'!$A$1,MATCH(Sheet1!A1,'MAR-21'!$A:$A,0),1,22,1))),0) -> 0 | I5: {=+IFERROR(SUM(SUMIF(OFFSET('MAR-21'!$A$1,MATCH(Sheet1!A1,'MAR-21'!$A:$A,0),0,22,1),{"Basic*Arr*","7th Pay* Arr*"},OFFSET('MAR-21'!$A$1,MATCH(Sheet1!A1,'MAR-21'!$A:$A,0),1,22,1))),0)} -> 0 | J5: =+SUM(C5:I5) -> 0 | K5: =IFERROR(SUM(SUMIF(OFFSET('MAR-21'!$A$1,MATCH(Sheet1!A1,'MAR-21'!$A:$A,0),2,22,1),{"*Pro*ax*"},OFFSET('MAR-21'!$A$1,MATCH(Sheet1!A1,'MAR-21'!$A:$A,0),3,22,1))),0) -> 0 | L5: =IFERROR(SUM(SUMIF(OFFSET('MAR-21'!$A$1,MATCH(Sheet1!A1,'MAR-21'!$A:$A,0),2,22,1),{"GPF_G*","DCPS"},OFFSET('MAR-21'!$A$1,MATCH(Sheet1!A1,'MAR-21'!$A:$A,0),3,22,1))),0) -> 0 | M5: =IFERROR(SUM(SUMIF(OFFSET('MAR-21'!$A$1,MATCH(Sheet1!A1,'MAR-21'!$A:$A,0),2,22,1),{"*GIS","GIS*R"},OFFSET('MAR-21'!$A$1,MATCH(Sheet1!A1,'MAR-21'!$A:$A,0),3,22,1))),0) -> 0 | N5: =IFERROR(SUM(SUMIF(OFFSET('MAR-21'!$A$1,MATCH(Sheet1!A1,'MAR-21'!$A:$A,0),5,22,1),{"LI*1"},OFFSET('MAR-21'!$A$1,MATCH(Sheet1!A1,'MAR-21'!$A:$A,0),6,22,1))),0) -> 0 | O5: {=IFERROR(SUM(SUMIF(OFFSET('MAR-21'!$A$1,MATCH(Sheet1!A1,'MAR-21'!$A:$A,0),2,22,1),{"*HB*USE","HB*INT"},OFFSET('MAR-21'!$A$1,MATCH(Sheet1!A1,'MAR-21'!$A:$A,0),3,22,1))),0)} -> 0 | P5: {=IFERROR(SUM(SUMIF(OFFSET('MAR-21'!$A$1,MATCH(Sheet1!A1,'MAR-21'!$A:$A,0),5,22,1),{"OTHE*1","CO.*1","OTHE*2","WEL*ND","BAN*1","CLU*ND","RD*1","LI*2","MIS*US","*TAINAN*","MCA*INT*","MAIN*NANCE*","*C M Relief Fund*","Co. Op. Hsg Soc.*","GPF_ADV*","Co. Op. Cr. Soc. 2*","DCPS DA","DCPS Pay","MCA Int"},OFFSET('MAR-21'!$A$1,MATCH(Sheet1!A1,'MAR-21'!$A:$A,0),6,22,1)))+SUM(SUMIF(OFFSET('MAR-21'!$A$1,MATCH(Sheet1!A1,'MAR-21'!$A:$A,0),2,22,1),{"MCA","COM*DV*","HB*ND","CO*SOC","HRR","SRV*H","ACC*CY","F.A","STAMP_REVENUE","*C M Relief Fund*","GPF_ADV*","Co. Op. Cr. Soc. 2*","DCPS DA","DCPS Pay","MCA Int"},OFFSET('MAR-21'!$A$1,MATCH(Sheet1!A1,'MAR-21'!$A:$A,0),3,22,1))),0)} -> 0 | Q5: =+J5-H5-K5-L5-M5-N5-O5-P5-R5 -> 0 | R5: =IFERROR(SUM(SUMIF(OFFSET('MAR-21'!$A$1,MATCH(Sheet1!A1,'MAR-21'!$A:$A,0),2,22,1),{"*I.*ax*"},OFFSET('MAR-21'!$A$1,MATCH(Sheet1!A1,'MAR-21'!$A:$A,0),3,22,1))),0) -> 0 | S5: {=+IFERROR(IF(OFFSET('MAR-21'!$B$1,MATCH(Sheet1!A1,'MAR-21'!B:B,0)-2,0,1,1)=Sheet1!J5,IF(MID(IFERROR(OFFSET('MAR-21'!$B$1,MATCH(Sheet1!A1,'MAR-21'!$B:$B,0)-1,-1,1,1),"GROSS ERROR"),11,FIND(" ",OFFSET('MAR-21'!$B$1,MATCH(Sheet1!A1,'MAR-21'!$B:$B,0)-1,-1,1,1),12)-11)-Q5=0,"","NET MISMATCH"),"GROSS MISMATCH"),"")} | U5: 2 | V5: =+IF(M25=M28,"NO","YES") -> NO | W5: =+G2 -> PAN | X5: =+A1 -> 0 | Y5: =+D24 -> 0 | Z5: 0 | AA5: 0 | AB5: =+SUM(Y5:AA5) -> 0 | AC5: =+D26 -> 50000 | AD5: =+D28 -> 0 | AE5: =+D30 -> 0 | AF5: =+D29+D27+D31 -> 0 | AG5: =+AB5-SUM(AC5:AF5) -> -50000 | AH5: =+IF(D32>=200000,-200000,-D32) -> 0 | AI5: 0 | AJ5: =+AG5+AH5+AI5 -> -50000 | AK5: =+IF(H41>0,H36-H25,H36) -> 0 | AL5: {=+IF(IF(AND((AK5+AN5)>=150000,AK5>=150000),150000-AN5,AK5)<0,0,IF(AND((AK5+AN5)>=150000,AK5>=150000),150000-AN5,IF(AND(SUM(AK5+AN5)>150000,AK5<150000),150000-AN5,AK5)))} -> 0 | AM5: =+IF(H20>0,L20,0) -> 0 | AN5: =+AM5-AO5 -> 0 | AO5: =+IF(AND(H20>0,L20>50000),50000,IF(H20>0,L20,0)) -> 0 | AP5: =+H20 -> 0 | AQ5: =+H43 -> 0 | AR5: =+H45 -> 0 | AS5: =+H42 -> 0 | AT5: =+H44 -> 0 | AU5: =+SUM(AQ5:AT5)+AP5+AO5+AN5+AL5 -> 0 | AV5: =+AJ5-AU5 -> -50000 | AW5: =+M28 -> 0 | AX5: =+M30 -> 0 | AY5: =+M32 -> 0 | AZ5: =+M35 -> 0 | BA5: =+AW5-AX5+AY5-AZ5 -> 0 | BB5: =+M34 -> 0 | BC5: 0 | BD5: =+BB5+BC5 -> 0 | BE5: =+BA5-BD5 -> 0 | BF5: =+IF(AV5=M24,"","NOT OK") | BH5: =+G2 -> PAN | BI5: =+A1 -> 0 | BJ5: {=IFERROR(OFFSET('MAR-21'!$B$1,MATCH(Sheet1!A1,'MAR-21'!$B:$B,0)+1,0,1,1),"")} | BK5: =+J5 -> 0 | BL5: =+R5 -> 0 | BM5: {=IFERROR(OFFSET('MAR-21'!$A$1,MATCH(Sheet1!A1,'MAR-21'!$A:$A,0)-2,0,1,1),"")}
A6: 2 | B6: 44287 | C6: =IFERROR(SUM(SUMIF(OFFSET('APR-21'!$A$1,MATCH(Sheet1!A1,'APR-21'!$A:$A,0),0,22,1),{"BA*C","BASIC??"},OFFSET('APR-21'!$A$1,MATCH(Sheet1!A1,'APR-21'!$A:$A,0),1,22,1))),0) -> 0 | D6: =IFERROR(SUM(SUMIF(OFFSET('APR-21'!$A$1,MATCH(Sheet1!A1,'APR-21'!$A:$A,0),0,22,1),{"DA*C","D. *"},OFFSET('APR-21'!$A$1,MATCH(Sheet1!A1,'APR-21'!$A:$A,0),1,22,1))),0) -> 0 | E6: {=+IFERROR(SUM(SUMIF(OFFSET('APR-21'!$A$1,MATCH(Sheet1!A1,'APR-21'!$A:$A,0),0,22,1),{"H. R. A."},OFFSET('APR-21'!$A$1,MATCH(Sheet1!A1,'APR-21'!$A:$A,0),1,22,1))),0)} -> 0 | F6: =IFERROR(SUM(SUMIF(OFFSET('APR-21'!$A$1,MATCH(Sheet1!A1,'APR-21'!$A:$A,0),0,22,1),{"SP*AY*","S D A*","O.A.*","CLA (5th Pay)*","REF. Allow*","Trans.Allw.*","LF*","P. O.*","ARM*","Conv.A*","Otr.Allow*","Trans_Arrear*","BMIA*","Incentives*","Fit Allow*","KMA","NON-*","U.*","ME*A","PG*","Per.Tra"},OFFSET('APR-21'!$A$1,MATCH(Sheet1!A1,'APR-21'!$A:$A,0),1,22,1))),0) -> 0 | G6: =IFERROR(SUM(SUMIF(OFFSET('APR-21'!$A$1,MATCH(Sheet1!A1,'APR-21'!$A:$A,0),0,22,1),{"WA"},OFFSET('APR-21'!$A$1,MATCH(Sheet1!A1,'APR-21'!$A:$A,0),1,22,1))),0) -> 0 | H6: =IFERROR(SUM(SUMIF(OFFSET('APR-21'!$A$1,MATCH(Sheet1!A1,'APR-21'!$A:$A,0),0,22,1),{"DCPS","GROSS_ADJUST"},OFFSET('APR-21'!$A$1,MATCH(Sheet1!A1,'APR-21'!$A:$A,0),1,22,1))),0) -> 0 | I6: {=+IFERROR(SUM(SUMIF(OFFSET('APR-21'!$A$1,MATCH(Sheet1!A1,'APR-21'!$A:$A,0),0,22,1),{"Arr*","7th Pay* Arr*","Basic Arr."},OFFSET('APR-21'!$A$1,MATCH(Sheet1!A1,'APR-21'!$A:$A,0),1,22,1))),0)} -> 0 | J6: =SUM(C6:I6) -> 0 | K6: =IFERROR(SUM(SUMIF(OFFSET('APR-21'!$A$1,MATCH(Sheet1!A1,'APR-21'!$A:$A,0),2,22,1),{"*Pro*ax*"},OFFSET('APR-21'!$A$1,MATCH(Sheet1!A1,'APR-21'!$A:$A,0),3,22,1))),0) -> 0 | L6: =IFERROR(SUM(SUMIF(OFFSET('APR-21'!$A$1,MATCH(Sheet1!A1,'APR-21'!$A:$A,0),2,22,1),{"GPF_G*","DCPS"},OFFSET('APR-21'!$A$1,MATCH(Sheet1!A1,'APR-21'!$A:$A,0),3,22,1))),0) -> 0 | M6: =IFERROR(SUM(SUMIF(OFFSET('APR-21'!$A$1,MATCH(Sheet1!A1,'APR-21'!$A:$A,0),2,22,1),{"*GIS","GIS*R"},OFFSET('APR-21'!$A$1,MATCH(Sheet1!A1,'APR-21'!$A:$A,0),3,22,1))),0) -> 0 | N6: =IFERROR(SUM(SUMIF(OFFSET('APR-21'!$A$1,MATCH(Sheet1!A1,'APR-21'!$A:$A,0),5,22,1),{"LI*1"},OFFSET('APR-21'!$A$1,MATCH(Sheet1!A1,'APR-21'!$A:$A,0),6,22,1))),0) -> 0 | O6: {=IFERROR(SUM(SUMIF(OFFSET('APR-21'!$A$1,MATCH(Sheet1!A1,'APR-21'!$A:$A,0),2,22,1),{"HB*USE","HB*INT"},OFFSET('APR-21'!$A$1,MATCH(Sheet1!A1,'APR-21'!$A:$A,0),3,22,1))),0)} -> 0 | P6: {=IFERROR(SUM(SUMIF(OFFSET('APR-21'!$A$1,MATCH(Sheet1!A1,'APR-21'!$A:$A,0),5,22,1),{"OTHE*1","CO.*1","OTHE*2","WEL*ND","BAN*1","CLU*ND","RD*1","LI*2","MIS*US","*TAINAN*","MCA*INT*","MAIN*NANCE*","*C M Relief Fund*","Co. Op. Hsg Soc.*","GPF_ADV*","Co. Op. Cr. Soc. 2*","DCPS DA","DCPS Pay","MCA Int"},OFFSET('APR-21'!$A$1,MATCH(Sheet1!A1,'APR-21'!$A:$A,0),6,22,1)))+SUM(SUMIF(OFFSET('APR-21'!$A$1,MATCH(Sheet1!A1,'APR-21'!$A:$A,0),2,22,1),{"MCA","COM*DV*","HB*ND","CO*SOC","HRR","SRV*H","ACC*CY","F.A","STAMP_REVENUE","*C M Relief Fund*","GPF_ADV*","Co. Op. Cr. Soc. 2*","DCPS DA","DCPS Pay","MCA Int"},OFFSET('APR-21'!$A$1,MATCH(Sheet1!A1,'APR-21'!$A:$A,0),3,22,1))),0)} -> 0 | Q6: =+J6-H6-K6-L6-M6-N6-O6-P6-R6 -> 0 | R6: {=IFERROR(SUM(SUMIF(OFFSET('APR-21'!$A$1,MATCH(Sheet1!A1,'APR-21'!$A:$A,0),2,22,1),{"*I. *ax*"},OFFSET('APR-21'!$A$1,MATCH(Sheet1!A1,'APR-21'!$A:$A,0),3,22,1))),0)} -> 0 | S6: {=+IFERROR(IF(OFFSET('APR-21'!$B$1,MATCH(Sheet1!A1,'APR-21'!B:B,0)-2,0,1,1)=Sheet1!J6,IF(MID(IFERROR(OFFSET('APR-21'!$B$1,MATCH(Sheet1!A1,'APR-21'!$B:$B,0)-1,-1,1,1),"GROSS ERROR"),11,FIND(" ",OFFSET('APR-21'!$B$1,MATCH(Sheet1!A1,'APR-21'!$B:$B,0)-1,-1,1,1),12)-11)-Q6=0,"","NET MISMATCH"),"GROSS MISMATCH"),"")} | BH6: =+G2 -> PAN | BI6: =+A1 -> 0 | BJ6: {=IFERROR(OFFSET('APR-21'!$B$1,MATCH(Sheet1!A1,'APR-21'!$B:$B,0)+1,0,1,1),"")} | BK6: =+J6 -> 0 | BL6: =+R6 -> 0 | BM6: {=IFERROR(OFFSET('APR-21'!$A$1,MATCH(Sheet1!A1,'APR-21'!$A:$A,0)-2,0,1,1),"")}
A7: 3 | B7: 44317 | C7: =IFERROR(SUM(SUMIF(OFFSET('MAY-21'!$A$1,MATCH(Sheet1!A1,'MAY-21'!$A:$A,0),0,22,1),{"BA*C","BASIC??"},OFFSET('MAY-21'!$A$1,MATCH(Sheet1!A1,'MAY-21'!$A:$A,0),1,22,1))),0) -> 0 | D7: =IFERROR(SUM(SUMIF(OFFSET('MAY-21'!$A$1,MATCH(Sheet1!A1,'MAY-21'!$A:$A,0),0,22,1),{"DA*C","D. *"},OFFSET('MAY-21'!$A$1,MATCH(Sheet1!A1,'MAY-21'!$A:$A,0),1,22,1))),0) -> 0 | E7: =IFERROR(SUM(SUMIF(OFFSET('MAY-21'!$A$1,MATCH(Sheet1!A1,'MAY-21'!$A:$A,0),0,22,1),{"H. R. A."},OFFSET('MAY-21'!$A$1,MATCH(Sheet1!A1,'MAY-21'!$A:$A,0),1,22,1))),0) -> 0 | F7: {=IFERROR(SUM(SUMIF(OFFSET('MAY-21'!$A$1,MATCH(Sheet1!A1,'MAY-21'!$A:$A,0),0,22,1),{"SP*AY*","S D A*","O.A.*","CLA (5th Pay)*","REF. Allow*","Trans.Allw.*","LF*","P. O.*","ARM*","Conv.A*","Otr.Allow*","Trans_Arrear*","BMIA*","Incentives*","Fit Allow*","KMA","NON-*","U.*","ME*A","PG*","Per.Tra"},OFFSET('MAY-21'!$A$1,MATCH(Sheet1!A1,'MAY-21'!$A:$A,0),1,22,1))),0)} -> 0 | G7: =IFERROR(SUM(SUMIF(OFFSET('MAY-21'!$A$1,MATCH(Sheet1!A1,'MAY-21'!$A:$A,0),0,22,1),{"WA"},OFFSET('MAY-21'!$A$1,MATCH(Sheet1!A1,'MAY-21'!$A:$A,0),1,22,1))),0) -> 0 | H7: =IFERROR(SUM(SUMIF(OFFSET('MAY-21'!$A$1,MATCH(Sheet1!A1,'MAY-21'!$A:$A,0),0,22,1),{"DCPS","GROSS_ADJUST"},OFFSET('MAY-21'!$A$1,MATCH(Sheet1!A1,'MAY-21'!$A:$A,0),1,22,1))),0) -> 0 | I7: {=+IFERROR(SUM(SUMIF(OFFSET('MAY-21'!$A$1,MATCH(Sheet1!A1,'MAY-21'!$A:$A,0),0,22,1),{"Arr*","7th Pay* Arr*","Basic Arr.","DA Arr"},OFFSET('MAY-21'!$A$1,MATCH(Sheet1!A1,'MAY-21'!$A:$A,0),1,22,1))),0)} -> 0 | J7: =SUM(C7:I7) -> 0 | K7: =IFERROR(SUM(SUMIF(OFFSET('MAY-21'!$A$1,MATCH(Sheet1!A1,'MAY-21'!$A:$A,0),2,22,1),{"*Pro*ax*"},OFFSET('MAY-21'!$A$1,MATCH(Sheet1!A1,'MAY-21'!$A:$A,0),3,22,1))),0) -> 0 | L7: =IFERROR(SUM(SUMIF(OFFSET('MAY-21'!$A$1,MATCH(Sheet1!A1,'MAY-21'!$A:$A,0),2,22,1),{"GPF_G*","DCPS"},OFFSET('MAY-21'!$A$1,MATCH(Sheet1!A1,'MAY-21'!$A:$A,0),3,22,1))),0) -> 0 | M7: =IFERROR(SUM(SUMIF(OFFSET('MAY-21'!$A$1,MATCH(Sheet1!A1,'MAY-21'!$A:$A,0),2,22,1),{"*GIS","GIS*R"},OFFSET('MAY-21'!$A$1,MATCH(Sheet1!A1,'MAY-21'!$A:$A,0),3,22,1))),0) -> 0 | N7: =IFERROR(SUM(SUMIF(OFFSET('MAY-21'!$A$1,MATCH(Sheet1!A1,'MAY-21'!$A:$A,0),5,22,1),{"LI*1"},OFFSET('MAY-21'!$A$1,MATCH(Sheet1!A1,'MAY-21'!$A:$A,0),6,22,1))),0) -> 0 | O7: {=IFERROR(SUM(SUMIF(OFFSET('MAY-21'!$A$1,MATCH(Sheet1!A1,'MAY-21'!$A:$A,0),2,22,1),{"HB*USE","HB*INT"},OFFSET('MAY-21'!$A$1,MATCH(Sheet1!A1,'MAY-21'!$A:$A,0),3,22,1))),0)} -> 0 | P7: {=IFERROR(SUM(SUMIF(OFFSET('MAY-21'!$A$1,MATCH(Sheet1!A1,'MAY-21'!$A:$A,0),5,22,1),{"OTHE*1","CO.*1","OTHE*2","WEL*ND","BAN*1","CLU*ND","RD*1","LI*2","MIS*US","*TAINAN*","MCA*INT*","MAIN*NANCE*","*C M Relief Fund*","Co. Op. Hsg Soc.*","GPF_ADV*","Co. Op. Cr. Soc. 2*","DCPS DA","DCPS Pay","MCA Int"},OFFSET('MAY-21'!$A$1,MATCH(Sheet1!A1,'MAY-21'!$A:$A,0),6,22,1)))+SUM(SUMIF(OFFSET('MAY-21'!$A$1,MATCH(Sheet1!A1,'MAY-21'!$A:$A,0),2,22,1),{"MCA","COM*DV*","HB*ND","CO*SOC","HRR","SRV*H","ACC*CY","F.A","STAMP_REVENUE","*C M Relief Fund*","GPF_ADV*","Co. Op. Cr. Soc. 2*","DCPS DA","DCPS Pay","MCA Int"},OFFSET('MAY-21'!$A$1,MATCH(Sheet1!A1,'MAY-21'!$A:$A,0),3,22,1))),0)} -> 0 | Q7: =+J7-H7-K7-L7-M7-N7-O7-P7-R7 -> 0 | R7: =IFERROR(SUM(SUMIF(OFFSET('MAY-21'!$A$1,MATCH(Sheet1!A1,'MAY-21'!$A:$A,0),2,22,1),{"*I. *ax*"},OFFSET('MAY-21'!$A$1,MATCH(Sheet1!A1,'MAY-21'!$A:$A,0),3,22,1))),0) -> 0 | S7: {=+IFERROR(IF(OFFSET('MAY-21'!$B$1,MATCH(Sheet1!A1,'MAY-21'!B:B,0)-2,0,1,1)=Sheet1!J7,IF(MID(IFERROR(OFFSET('MAY-21'!$B$1,MATCH(Sheet1!A1,'MAY-21'!$B:$B,0)-1,-1,1,1),"GROSS ERROR"),11,FIND(" ",OFFSET('MAY-21'!$B$1,MATCH(Sheet1!A1,'MAY-21'!$B:$B,0)-1,-1,1,1),12)-11)-Q7=0,"","NET MISMATCH"),"GROSS MISMATCH"),"")} | BH7: =+G2 -> PAN | BI7: =+A1 -> 0 | BJ7: {=IFERROR(OFFSET('MAY-21'!$B$1,MATCH(Sheet1!A1,'MAY-21'!$B:$B,0)+1,0,1,1),"")} | BK7: =+J7 -> 0 | BL7: =+R7 -> 0 | BM7: {=+IFERROR(OFFSET('MAY-21'!$A$1,MATCH(Sheet1!A1,'MAY-21'!$A:$A,0)-2,0,1,1),"")}
A8: 4 | B8: 44348 | C8: =IFERROR(SUM(SUMIF(OFFSET('JUN-21'!$A$1,MATCH(Sheet1!A1,'JUN-21'!$A:$A,0),0,22,1),{"BA*C","BASIC??"},OFFSET('JUN-21'!$A$1,MATCH(Sheet1!A1,'JUN-21'!$A:$A,0),1,22,1))),0) -> 0 | D8: =IFERROR(SUM(SUMIF(OFFSET('JUN-21'!$A$1,MATCH(Sheet1!A1,'JUN-21'!$A:$A,0),0,22,1),{"DA*C","D. *"},OFFSET('JUN-21'!$A$1,MATCH(Sheet1!A1,'JUN-21'!$A:$A,0),1,22,1))),0) -> 0 | E8: =IFERROR(SUM(SUMIF(OFFSET('JUN-21'!$A$1,MATCH(Sheet1!A1,'JUN-21'!$A:$A,0),0,22,1),{"H. R. A."},OFFSET('JUN-21'!$A$1,MATCH(Sheet1!A1,'JUN-21'!$A:$A,0),1,22,1))),0) -> 0 | F8: {=IFERROR(SUM(SUMIF(OFFSET('JUN-21'!$A$1,MATCH(Sheet1!A1,'JUN-21'!$A:$A,0),0,22,1),{"SP*AY*","S D A*","O.A.*","CLA (5th Pay)*","REF. Allow*","Trans.Allw.*","LF*","P. O.*","ARM*","Conv.A*","Otr.Allow*","Trans_Arrear*","BMIA*","Incentives*","Fit Allow*","KMA","NON-*","U.*","ME*A","PG*","Per.Tra"},OFFSET('JUN-21'!$A$1,MATCH(Sheet1!A1,'JUN-21'!$A:$A,0),1,22,1))),0)} -> 0 | G8: =IFERROR(SUM(SUMIF(OFFSET('JUN-21'!$A$1,MATCH(Sheet1!A1,'JUN-21'!$A:$A,0),0,22,1),{"WA"},OFFSET('JUN-21'!$A$1,MATCH(Sheet1!A1,'JUN-21'!$A:$A,0),1,22,1))),0) -> 0 | H8: =IFERROR(SUM(SUMIF(OFFSET('JUN-21'!$A$1,MATCH(Sheet1!A1,'JUN-21'!$A:$A,0),0,22,1),{"DCPS","GROSS_ADJUST"},OFFSET('JUN-21'!$A$1,MATCH(Sheet1!A1,'JUN-21'!$A:$A,0),1,22,1))),0) -> 0 | I8: {=+IFERROR(SUM(SUMIF(OFFSET('JUN-21'!$A$1,MATCH(Sheet1!A1,'JUN-21'!$A:$A,0),0,22,1),{"Basic*Arr*","7th Pay* Arr*"},OFFSET('JUN-21'!$A$1,MATCH(Sheet1!A1,'JUN-21'!$A:$A,0),1,22,1))),0)} -> 0 | J8: =SUM(C8:I8) -> 0 | K8: =IFERROR(SUM(SUMIF(OFFSET('JUN-21'!$A$1,MATCH(Sheet1!A1,'JUN-21'!$A:$A,0),2,22,1),{"*Pro*ax*"},OFFSET('JUN-21'!$A$1,MATCH(Sheet1!A1,'JUN-21'!$A:$A,0),3,22,1))),0) -> 0 | L8: =IFERROR(SUM(SUMIF(OFFSET('JUN-21'!$A$1,MATCH(Sheet1!A1,'JUN-21'!$A:$A,0),2,22,1),{"GPF_G*","DCPS"},OFFSET('JUN-21'!$A$1,MATCH(Sheet1!A1,'JUN-21'!$A:$A,0),3,22,1))),0) -> 0 | M8: =IFERROR(SUM(SUMIF(OFFSET('JUN-21'!$A$1,MATCH(Sheet1!A1,'JUN-21'!$A:$A,0),2,22,1),{"*GIS","GIS*R"},OFFSET('JUN-21'!$A$1,MATCH(Sheet1!A1,'JUN-21'!$A:$A,0),3,22,1))),0) -> 0 | N8: =IFERROR(SUM(SUMIF(OFFSET('JUN-21'!$A$1,MATCH(Sheet1!A1,'JUN-21'!$A:$A,0),5,22,1),{"LI*1"},OFFSET('JUN-21'!$A$1,MATCH(Sheet1!A1,'JUN-21'!$A:$A,0),6,22,1))),0) -> 0 | O8: {=IFERROR(SUM(SUMIF(OFFSET('JUN-21'!$A$1,MATCH(Sheet1!A1,'JUN-21'!$A:$A,0),2,22,1),{"HB*USE","HB*INT"},OFFSET('JUN-21'!$A$1,MATCH(Sheet1!A1,'JUN-21'!$A:$A,0),3,22,1))),0)} -> 0 | P8: {=IFERROR(SUM(SUMIF(OFFSET('JUN-21'!$A$1,MATCH(Sheet1!A1,'JUN-21'!$A:$A,0),5,22,1),{"OTHE*1","CO.*1","OTHE*2","WEL*ND","BAN*1","CLU*ND","RD*1","LI*2","MIS*US","*TAINAN*","MCA*INT*","MAIN*NANCE*","*C M Relief Fund*","Co. Op. Hsg Soc.*","GPF_ADV*","Co. Op. Cr. Soc. 2*","DCPS DA","DCPS Pay","MCA Int"},OFFSET('JUN-21'!$A$1,MATCH(Sheet1!A1,'JUN-21'!$A:$A,0),6,22,1)))+SUM(SUMIF(OFFSET('JUN-21'!$A$1,MATCH(Sheet1!A1,'JUN-21'!$A:$A,0),2,22,1),{"MCA","COM*DV*","HB*ND","CO*SOC","HRR","SRV*H","ACC*CY","F.A","STAMP_REVENUE","*C M Relief Fund*","GPF_ADV*","Co. Op. Cr. Soc. 2*","DCPS DA","DCPS Pay","MCA Int"},OFFSET('JUN-21'!$A$1,MATCH(Sheet1!A1,'JUN-21'!$A:$A,0),3,22,1))),0)} -> 0 | Q8: =+J8-H8-K8-L8-M8-N8-O8-P8-R8 -> 0 | R8: {=IFERROR(SUM(SUMIF(OFFSET('JUN-21'!$A$1,MATCH(Sheet1!A1,'JUN-21'!$A:$A,0),2,22,1),{"*I. *ax*"},OFFSET('JUN-21'!$A$1,MATCH(Sheet1!A1,'JUN-21'!$A:$A,0),3,22,1))),0)} -> 0 | S8: {=+IFERROR(IF(OFFSET('JUN-21'!$B$1,MATCH(Sheet1!A1,'JUN-21'!B:B,0)-2,0,1,1)=Sheet1!J8,IF(MID(IFERROR(OFFSET('JUN-21'!$B$1,MATCH(Sheet1!A1,'JUN-21'!$B:$B,0)-1,-1,1,1),"GROSS ERROR"),11,FIND(" ",OFFSET('JUN-21'!$B$1,MATCH(Sheet1!A1,'JUN-21'!$B:$B,0)-1,-1,1,1),12)-11)-Q8=0,"","NET MISMATCH"),"GROSS MISMATCH"),"")} | BH8: =+G2 -> PAN | BI8: =+A1 -> 0 | BJ8: {=IFERROR(OFFSET('JUN-21'!$B$1,MATCH(Sheet1!A1,'JUN-21'!$B:$B,0)+1,0,1,1),"")} | BK8: =+J8 -> 0 | BL8: =+R8 -> 0 | BM8: {=IFERROR(OFFSET('JUN-21'!$A$1,MATCH(Sheet1!A1,'JUN-21'!$A:$A,0)-2,0,1,1),"")}
A9: 5 | B9: 44378 | C9: =IFERROR(SUM(SUMIF(OFFSET('JUL-21'!$A$1,MATCH(Sheet1!A1,'JUL-21'!$A:$A,0),0,22,1),{"BA*C","BASIC??"},OFFSET('JUL-21'!$A$1,MATCH(Sheet1!A1,'JUL-21'!$A:$A,0),1,22,1))),0) -> 0 | D9: =IFERROR(SUM(SUMIF(OFFSET('JUL-21'!$A$1,MATCH(Sheet1!A1,'JUL-21'!$A:$A,0),0,22,1),{"DA*C","D. *"},OFFSET('JUL-21'!$A$1,MATCH(Sheet1!A1,'JUL-21'!$A:$A,0),1,22,1))),0) -> 0 | E9: =IFERROR(SUM(SUMIF(OFFSET('JUL-21'!$A$1,MATCH(Sheet1!A1,'JUL-21'!$A:$A,0),0,22,1),{"H. R. A."},OFFSET('JUL-21'!$A$1,MATCH(Sheet1!A1,'JUL-21'!$A:$A,0),1,22,1))),0) -> 0 | F9: {=IFERROR(SUM(SUMIF(OFFSET('JUL-21'!$A$1,MATCH(Sheet1!A1,'JUL-21'!$A:$A,0),0,22,1),{"SP*AY*","S D A*","O.A.*","CLA (5th Pay)*","REF. Allow*","Trans.Allw.*","LF*","P. O.*","ARM*","Conv.A*","Otr.Allow*","Trans_Arrear*","BMIA*","Incentives*","Fit Allow*","KMA","NON-*","U.*","ME*A","PG*","Per.Tra"},OFFSET('JUL-21'!$A$1,MATCH(Sheet1!A1,'JUL-21'!$A:$A,0),1,22,1))),0)} -> 0 | G9: =IFERROR(SUM(SUMIF(OFFSET('JUL-21'!$A$1,MATCH(Sheet1!A1,'JUL-21'!$A:$A,0),0,22,1),{"WA"},OFFSET('JUL-21'!$A$1,MATCH(Sheet1!A1,'JUL-21'!$A:$A,0),1,22,1))),0) -> 0 | H9: {=+IFERROR(SUM(SUMIF(OFFSET('JUL-21'!$A$1,MATCH(Sheet1!A1,'JUL-21'!$A:$A,0),0,22,1),{"DCPS","GROSS_ADJUST"},OFFSET('JUL-21'!$A$1,MATCH(Sheet1!A1,'JUL-21'!$A:$A,0),1,22,1))),0)} -> 0 | I9: {=++IFERROR(SUM(SUMIF(OFFSET('JUL-21'!$A$1,MATCH(Sheet1!A1,'JUL-21'!$A:$A,0),0,22,1),{"Basic*Arr*","7th Pay* Arr*"},OFFSET('JUL-21'!$A$1,MATCH(Sheet1!A1,'JUL-21'!$A:$A,0),1,22,1))),0)} -> 0 | J9: =SUM(C9:I9) -> 0 | K9: =IFERROR(SUM(SUMIF(OFFSET('JUL-21'!$A$1,MATCH(Sheet1!A1,'JUL-21'!$A:$A,0),2,22,1),{"*Pro*ax*"},OFFSET('JUL-21'!$A$1,MATCH(Sheet1!A1,'JUL-21'!$A:$A,0),3,22,1))),0) -> 0 | L9: =IFERROR(SUM(SUMIF(OFFSET('JUL-21'!$A$1,MATCH(Sheet1!A1,'JUL-21'!$A:$A,0),2,22,1),{"GPF_G*","DCPS"},OFFSET('JUL-21'!$A$1,MATCH(Sheet1!A1,'JUL-21'!$A:$A,0),3,22,1))),0) -> 0 | M9: =IFERROR(SUM(SUMIF(OFFSET('JUL-21'!$A$1,MATCH(Sheet1!A1,'JUL-21'!$A:$A,0),2,22,1),{"*GIS","GIS*R"},OFFSET('JUL-21'!$A$1,MATCH(Sheet1!A1,'JUL-21'!$A:$A,0),3,22,1))),0) -> 0 | N9: =IFERROR(SUM(SUMIF(OFFSET('JUL-21'!$A$1,MATCH(Sheet1!A1,'JUL-21'!$A:$A,0),5,22,1),{"LI*1"},OFFSET('JUL-21'!$A$1,MATCH(Sheet1!A1,'JUL-21'!$A:$A,0),6,22,1))),0) -> 0 | O9: {=IFERROR(SUM(SUMIF(OFFSET('JUL-21'!$A$1,MATCH(Sheet1!A1,'JUL-21'!$A:$A,0),2,22,1),{"HB*USE","HB*INT"},OFFSET('JUL-21'!$A$1,MATCH(Sheet1!A1,'JUL-21'!$A:$A,0),3,22,1))),0)} -> 0 | P9: {=IFERROR(SUM(SUMIF(OFFSET('JUL-21'!$A$1,MATCH(Sheet1!A1,'JUL-21'!$A:$A,0),5,22,1),{"OTHE*1","CO.*1","OTHE*2","WEL*ND","BAN*1","CLU*ND","RD*1","LI*2","MIS*US","*TAINAN*","MCA*INT*","MAIN*NANCE*","*C M Relief Fund*","Co. Op. Hsg Soc.*","GPF_ADV*","Co. Op. Cr. Soc. 2*","DCPS DA","DCPS Pay","MCA Int"},OFFSET('JUL-21'!$A$1,MATCH(Sheet1!A1,'JUL-21'!$A:$A,0),6,22,1)))+SUM(SUMIF(OFFSET('JUL-21'!$A$1,MATCH(Sheet1!A1,'JUL-21'!$A:$A,0),2,22,1),{"MCA","COM*DV*","HB*ND","CO*SOC","HRR","SRV*H","ACC*CY","F.A","STAMP_REVENUE","*C M Relief Fund*","GPF_ADV*","Co. Op. Cr. Soc. 2*","DCPS DA","DCPS Pay","MCA Int"},OFFSET('JUL-21'!$A$1,MATCH(Sheet1!A1,'JUL-21'!$A:$A,0),3,22,1))),0)} -> 0 | Q9: =+J9-H9-K9-L9-M9-N9-O9-P9-R9 -> 0 | R9: =IFERROR(SUM(SUMIF(OFFSET('JUL-21'!$A$1,MATCH(Sheet1!A1,'JUL-21'!$A:$A,0),2,22,1),{"*I. *ax*"},OFFSET('JUL-21'!$A$1,MATCH(Sheet1!A1,'JUL-21'!$A:$A,0),3,22,1))),0) -> 0 | S9: {=+IFERROR(IF(OFFSET('JUL-21'!$B$1,MATCH(Sheet1!A1,'JUL-21'!B:B,0)-2,0,1,1)=Sheet1!J9,IF(MID(IFERROR(OFFSET('JUL-21'!$B$1,MATCH(Sheet1!A1,'JUL-21'!$B:$B,0)-1,-1,1,1),"GROSS ERROR"),11,FIND(" ",OFFSET('JUL-21'!$B$1,MATCH(Sheet1!A1,'JUL-21'!$B:$B,0)-1,-1,1,1),12)-11)-Q9=0,"","NET MISMATCH"),"GROSS MISMATCH"),"")} | BH9: =+G2 -> PAN | BI9: =+A1 -> 0 | BJ9: {=+IFERROR(OFFSET('JUL-21'!$B$1,MATCH(Sheet1!A1,'JUL-21'!$B:$B,0)+1,0,1,1),"")} | BK9: =+J9 -> 0 | BL9: =+R9 -> 0 | BM9: {=IFERROR(OFFSET('JUL-21'!$A$1,MATCH(Sheet1!A1,'JUL-21'!$A:$A,0)-2,0,1,1),"")}
A10: 6 | B10: 44409 | C10: =IFERROR(SUM(SUMIF(OFFSET('AUG-21'!$A$1,MATCH(Sheet1!A1,'AUG-21'!$A:$A,0),0,22,1),{"BA*C","BASIC??"},OFFSET('AUG-21'!$A$1,MATCH(Sheet1!A1,'AUG-21'!$A:$A,0),1,22,1))),0) -> 0 | D10: =IFERROR(SUM(SUMIF(OFFSET('AUG-21'!$A$1,MATCH(Sheet1!A1,'AUG-21'!$A:$A,0),0,22,1),{"DA*C","D. *"},OFFSET('AUG-21'!$A$1,MATCH(Sheet1!A1,'AUG-21'!$A:$A,0),1,22,1))),0) -> 0 | E10: =IFERROR(SUM(SUMIF(OFFSET('AUG-21'!$A$1,MATCH(Sheet1!A1,'AUG-21'!$A:$A,0),0,22,1),{"H. R. A."},OFFSET('AUG-21'!$A$1,MATCH(Sheet1!A1,'AUG-21'!$A:$A,0),1,22,1))),0) -> 0 | F10: {=IFERROR(SUM(SUMIF(OFFSET('AUG-21'!$A$1,MATCH(Sheet1!A1,'AUG-21'!$A:$A,0),0,22,1),{"SP*AY*","S D A*","O.A.*","CLA (5th Pay)*","REF. Allow*","Trans.Allw.*","LF*","P. O.*","ARM*","Conv.A*","Otr.Allow*","Trans_Arrear*","BMIA*","Incentives*","Fit Allow*","KMA","NON-*","U.*","ME*A","PG*","Per.Tra"},OFFSET('AUG-21'!$A$1,MATCH(Sheet1!A1,'AUG-21'!$A:$A,0),1,22,1))),0)} -> 0 | G10: =IFERROR(SUM(SUMIF(OFFSET('AUG-21'!$A$1,MATCH(Sheet1!A1,'AUG-21'!$A:$A,0),0,22,1),{"WA"},OFFSET('AUG-21'!$A$1,MATCH(Sheet1!A1,'AUG-21'!$A:$A,0),1,22,1))),0) -> 0 | H10: =IFERROR(SUM(SUMIF(OFFSET('AUG-21'!$A$1,MATCH(Sheet1!A1,'AUG-21'!$A:$A,0),0,22,1),{"DCPS","GROSS_ADJUST"},OFFSET('AUG-21'!$A$1,MATCH(Sheet1!A1,'AUG-21'!$A:$A,0),1,22,1))),0) -> 0 | I10: {=+IFERROR(SUM(SUMIF(OFFSET('AUG-21'!$A$1,MATCH(Sheet1!A1,'AUG-21'!$A:$A,0),0,22,1),{"7th Pay* Arr*","Basic Arr*","DA Arr"},OFFSET('AUG-21'!$A$1,MATCH(Sheet1!A1,'AUG-21'!$A:$A,0),1,22,1))),0)} -> 0 | J10: =SUM(C10:I10) -> 0 | K10: =IFERROR(SUM(SUMIF(OFFSET('AUG-21'!$A$1,MATCH(Sheet1!A1,'AUG-21'!$A:$A,0),2,22,1),{"*Pro*ax*"},OFFSET('AUG-21'!$A$1,MATCH(Sheet1!A1,'AUG-21'!$A:$A,0),3,22,1))),0) -> 0 | L10: =IFERROR(SUM(SUMIF(OFFSET('AUG-21'!$A$1,MATCH(Sheet1!A1,'AUG-21'!$A:$A,0),2,22,1),{"GPF_G*","DCPS","*7thPay GP*"},OFFSET('AUG-21'!$A$1,MATCH(Sheet1!A1,'AUG-21'!$A:$A,0),3,22,1))),0) -> 0 | M10: =IFERROR(SUM(SUMIF(OFFSET('AUG-21'!$A$1,MATCH(Sheet1!A1,'AUG-21'!$A:$A,0),2,22,1),{"*GIS","GIS*R"},OFFSET('AUG-21'!$A$1,MATCH(Sheet1!A1,'AUG-21'!$A:$A,0),3,22,1))),0) -> 0 | N10: =IFERROR(SUM(SUMIF(OFFSET('AUG-21'!$A$1,MATCH(Sheet1!A1,'AUG-21'!$A:$A,0),5,22,1),{"LI*1"},OFFSET('AUG-21'!$A$1,MATCH(Sheet1!A1,'AUG-21'!$A:$A,0),6,22,1))),0) -> 0 | O10: {=IFERROR(SUM(SUMIF(OFFSET('AUG-21'!$A$1,MATCH(Sheet1!A1,'AUG-21'!$A:$A,0),2,22,1),{"HB*USE","HB*INT"},OFFSET('AUG-21'!$A$1,MATCH(Sheet1!A1,'AUG-21'!$A:$A,0),3,22,1))),0)} -> 0 | P10: {=IFERROR(SUM(SUMIF(OFFSET('AUG-21'!$A$1,MATCH(Sheet1!A1,'AUG-21'!$A:$A,0),5,22,1),{"OTHE*1","CO.*1","OTHE*2","WEL*ND","BAN*1","CLU*ND","RD*1","LI*2","MIS*US","*TAINAN*","MCA*INT*","MAIN*NANCE*","*C M Relief Fund*","Co. Op. Hsg Soc.*","GPF_ADV*","Co. Op. Cr. Soc. 2*","DCPS DA","DCPS Pay","MCA Int"},OFFSET('AUG-21'!$A$1,MATCH(Sheet1!A1,'AUG-21'!$A:$A,0),6,22,1)))+SUM(SUMIF(OFFSET('AUG-21'!$A$1,MATCH(Sheet1!A1,'AUG-21'!$A:$A,0),2,22,1),{"MCA","COM*DV*","HB*ND","CO*SOC","HRR","SRV*H","ACC*CY","F.A","STAMP_REVENUE","*C M Relief Fund*","GPF_ADV*","Co. Op. Cr. Soc. 2*","DCPS DA","DCPS Pay","MCA Int"},OFFSET('AUG-21'!$A$1,MATCH(Sheet1!A1,'AUG-21'!$A:$A,0),3,22,1))),0)} -> 0 | Q10: =+J10-H10-K10-L10-M10-N10-O10-P10-R10 -> 0 | R10: {=IFERROR(SUM(SUMIF(OFFSET('AUG-21'!$A$1,MATCH(Sheet1!A1,'AUG-21'!$A:$A,0),2,22,1),{"*I. *ax*"},OFFSET('AUG-21'!$A$1,MATCH(Sheet1!A1,'AUG-21'!$A:$A,0),3,22,1))),0)} -> 0 | S10: {=+IFERROR(IF(OFFSET('AUG-21'!$B$1,MATCH(Sheet1!A1,'AUG-21'!B:B,0)-2,0,1,1)=Sheet1!J10,IF(MID(IFERROR(OFFSET('AUG-21'!$B$1,MATCH(Sheet1!A1,'AUG-21'!$B:$B,0)-1,-1,1,1),"GROSS ERROR"),11,FIND(" ",OFFSET('AUG-21'!$B$1,MATCH(Sheet1!A1,'AUG-21'!$B:$B,0)-1,-1,1,1),12)-11)-Q10=0,"","NET MISMATCH"),"GROSS MISMATCH"),"")} | BH10: =+G2 -> PAN | BI10: =+A1 -> 0 | BJ10: {=IFERROR(OFFSET('AUG-21'!$B$1,MATCH(Sheet1!A1,'AUG-21'!$B:$B,0)+1,0,1,1),"")} | BK10: =+J10 -> 0 | BL10: =+R10 -> 0 | BM10: {=IFERROR(OFFSET('AUG-21'!$A$1,MATCH(Sheet1!A1,'AUG-21'!$A:$A,0)-2,0,1,1),"")}
A11: 7 | B11: 44440 | C11: =IFERROR(SUM(SUMIF(OFFSET('SEP-21'!$A$1,MATCH(Sheet1!A1,'SEP-21'!$A:$A,0),0,22,1),{"BA*C","BASIC??"},OFFSET('SEP-21'!$A$1,MATCH(Sheet1!A1,'SEP-21'!$A:$A,0),1,22,1))),0) -> 0 | D11: =IFERROR(SUM(SUMIF(OFFSET('SEP-21'!$A$1,MATCH(Sheet1!A1,'SEP-21'!$A:$A,0),0,22,1),{"DA*C","D. *"},OFFSET('SEP-21'!$A$1,MATCH(Sheet1!A1,'SEP-21'!$A:$A,0),1,22,1))),0) -> 0 | E11: =IFERROR(SUM(SUMIF(OFFSET('SEP-21'!$A$1,MATCH(Sheet1!A1,'SEP-21'!$A:$A,0),0,22,1),{"H. R. A."},OFFSET('SEP-21'!$A$1,MATCH(Sheet1!A1,'SEP-21'!$A:$A,0),1,22,1))),0) -> 0 | F11: {=IFERROR(SUM(SUMIF(OFFSET('SEP-21'!$A$1,MATCH(Sheet1!A1,'SEP-21'!$A:$A,0),0,22,1),{"SP*AY*","S D A*","O.A.*","CLA (5th Pay)*","REF. Allow*","Trans.Allw.*","LF*","P. O.*","ARM*","Conv.A*","Otr.Allow*","Trans_Arrear*","BMIA*","Incentives*","Fit Allow*","KMA","NON-*","U.*","ME*A","PG*","Per.Tra"},OFFSET('SEP-21'!$A$1,MATCH(Sheet1!A1,'SEP-21'!$A:$A,0),1,22,1))),0)} -> 0 | G11: =IFERROR(SUM(SUMIF(OFFSET('SEP-21'!$A$1,MATCH(Sheet1!A1,'SEP-21'!$A:$A,0),0,22,1),{"WA"},OFFSET('SEP-21'!$A$1,MATCH(Sheet1!A1,'SEP-21'!$A:$A,0),1,22,1))),0) -> 0 | H11: =IFERROR(SUM(SUMIF(OFFSET('SEP-21'!$A$1,MATCH(Sheet1!A1,'SEP-21'!$A:$A,0),0,22,1),{"DCPS","GROSS_ADJUST"},OFFSET('SEP-21'!$A$1,MATCH(Sheet1!A1,'SEP-21'!$A:$A,0),1,22,1))),0) -> 0 | I11: {=++IFERROR(SUM(SUMIF(OFFSET('SEP-21'!$A$1,MATCH(Sheet1!A1,'SEP-21'!$A:$A,0),0,22,1),{"Basic*Arr*","7th Pay* Arr*"},OFFSET('SEP-21'!$A$1,MATCH(Sheet1!A1,'SEP-21'!$A:$A,0),1,22,1))),0)} -> 0 | J11: =SUM(C11:I11) -> 0 | K11: =IFERROR(SUM(SUMIF(OFFSET('SEP-21'!$A$1,MATCH(Sheet1!A1,'SEP-21'!$A:$A,0),2,22,1),{"*Pro*ax*"},OFFSET('SEP-21'!$A$1,MATCH(Sheet1!A1,'SEP-21'!$A:$A,0),3,22,1))),0) -> 0 | L11: =IFERROR(SUM(SUMIF(OFFSET('SEP-21'!$A$1,MATCH(Sheet1!A1,'SEP-21'!$A:$A,0),2,22,1),{"GPF_G*","DCPS"},OFFSET('SEP-21'!$A$1,MATCH(Sheet1!A1,'SEP-21'!$A:$A,0),3,22,1))),0) -> 0 | M11: =IFERROR(SUM(SUMIF(OFFSET('SEP-21'!$A$1,MATCH(Sheet1!A1,'SEP-21'!$A:$A,0),2,22,1),{"*GIS","GIS*R"},OFFSET('SEP-21'!$A$1,MATCH(Sheet1!A1,'SEP-21'!$A:$A,0),3,22,1))),0) -> 0 | N11: =IFERROR(SUM(SUMIF(OFFSET('SEP-21'!$A$1,MATCH(Sheet1!A1,'SEP-21'!$A:$A,0),5,22,1),{"LI*1"},OFFSET('SEP-21'!$A$1,MATCH(Sheet1!A1,'SEP-21'!$A:$A,0),6,22,1))),0) -> 0 | O11: {=IFERROR(SUM(SUMIF(OFFSET('SEP-21'!$A$1,MATCH(Sheet1!A1,'SEP-21'!$A:$A,0),2,22,1),{"HB*USE","HB*INT"},OFFSET('SEP-21'!$A$1,MATCH(Sheet1!A1,'SEP-21'!$A:$A,0),3,22,1))),0)} -> 0 | P11: {=IFERROR(SUM(SUMIF(OFFSET('SEP-21'!$A$1,MATCH(Sheet1!A1,'SEP-21'!$A:$A,0),5,22,1),{"OTHE*1","CO.*1","OTHE*2","WEL*ND","BAN*1","CLU*ND","RD*1","LI*2","MIS*US","*TAINAN*","MCA*INT*","MAIN*NANCE*","*C M Relief Fund*","Co. Op. Hsg Soc.*","GPF_ADV*","Co. Op. Cr. Soc. 2*","DCPS DA","DCPS Pay","MCA Int"},OFFSET('SEP-21'!$A$1,MATCH(Sheet1!A1,'SEP-21'!$A:$A,0),6,22,1)))+SUM(SUMIF(OFFSET('SEP-21'!$A$1,MATCH(Sheet1!A1,'SEP-21'!$A:$A,0),2,22,1),{"MCA","COM*DV*","HB*ND","CO*SOC","HRR","SRV*H","ACC*CY","F.A","STAMP_REVENUE","*C M Relief Fund*","GPF_ADV*","Co. Op. Cr. Soc. 2*","DCPS DA","DCPS Pay","MCA Int"},OFFSET('SEP-21'!$A$1,MATCH(Sheet1!A1,'SEP-21'!$A:$A,0),3,22,1))),0)} -> 0 | Q11: =+J11-H11-K11-L11-M11-N11-O11-P11-R11 -> 0 | R11: {=IFERROR(SUM(SUMIF(OFFSET('SEP-21'!$A$1,MATCH(Sheet1!A1,'SEP-21'!$A:$A,0),2,22,1),{"*I. *ax*"},OFFSET('SEP-21'!$A$1,MATCH(Sheet1!A1,'SEP-21'!$A:$A,0),3,22,1))),0)} -> 0 | S11: {=+IFERROR(IF(OFFSET('SEP-21'!$B$1,MATCH(Sheet1!A1,'SEP-21'!B:B,0)-2,0,1,1)=Sheet1!J11,IF(MID(IFERROR(OFFSET('SEP-21'!$B$1,MATCH(Sheet1!A1,'SEP-21'!$B:$B,0)-1,-1,1,1),"GROSS ERROR"),11,FIND(" ",OFFSET('SEP-21'!$B$1,MATCH(Sheet1!A1,'SEP-21'!$B:$B,0)-1,-1,1,1),12)-11)-Q11=0,"","NET MISMATCH"),"GROSS MISMATCH"),"")} | BH11: =+G2 -> PAN | BI11: =+A1 -> 0 | BJ11: {=IFERROR(OFFSET('SEP-21'!$B$1,MATCH(Sheet1!A1,'SEP-21'!$B:$B,0)+1,0,1,1),"")} | BK11: =+J11 -> 0 | BL11: =+R11 -> 0 | BM11: {=IFERROR(OFFSET('SEP-21'!$A$1,MATCH(Sheet1!A1,'SEP-21'!$A:$A,0)-2,0,1,1),"")}
A12: 8 | B12: 44470 | C12: =IFERROR(SUM(SUMIF(OFFSET('OCT-21'!$A$1,MATCH(Sheet1!A1,'OCT-21'!$A:$A,0),0,22,1),{"BA*C","BASIC??"},OFFSET('OCT-21'!$A$1,MATCH(Sheet1!A1,'OCT-21'!$A:$A,0),1,22,1))),0) -> 0 | D12: =IFERROR(SUM(SUMIF(OFFSET('OCT-21'!$A$1,MATCH(Sheet1!A1,'OCT-21'!$A:$A,0),0,22,1),{"DA*C","D. *"},OFFSET('OCT-21'!$A$1,MATCH(Sheet1!A1,'OCT-21'!$A:$A,0),1,22,1))),0) -> 0 | E12: =IFERROR(SUM(SUMIF(OFFSET('OCT-21'!$A$1,MATCH(Sheet1!A1,'OCT-21'!$A:$A,0),0,22,1),{"H. R. A."},OFFSET('OCT-21'!$A$1,MATCH(Sheet1!A1,'OCT-21'!$A:$A,0),1,22,1))),0) -> 0 | F12: {=IFERROR(SUM(SUMIF(OFFSET('OCT-21'!$A$1,MATCH(Sheet1!A1,'OCT-21'!$A:$A,0),0,22,1),{"SP*AY*","S D A*","O.A.*","CLA (5th Pay)*","REF. Allow*","Trans.Allw.*","LF*","P. O.*","ARM*","Conv.A*","Otr.Allow*","Trans_Arrear*","BMIA*","Incentives*","Fit Allow*","KMA","NON-*","U.*","ME*A","PG*","Per.Tra"},OFFSET('OCT-21'!$A$1,MATCH(Sheet1!A1,'OCT-21'!$A:$A,0),1,22,1))),0)} -> 0 | G12: =IFERROR(SUM(SUMIF(OFFSET('OCT-21'!$A$1,MATCH(Sheet1!A1,'OCT-21'!$A:$A,0),0,22,1),{"WA"},OFFSET('OCT-21'!$A$1,MATCH(Sheet1!A1,'OCT-21'!$A:$A,0),1,22,1))),0) -> 0 | H12: =IFERROR(SUM(SUMIF(OFFSET('OCT-21'!$A$1,MATCH(Sheet1!A1,'OCT-21'!$A:$A,0),0,22,1),{"DCPS","GROSS_ADJUST"},OFFSET('OCT-21'!$A$1,MATCH(Sheet1!A1,'OCT-21'!$A:$A,0),1,22,1))),0) -> 0 | I12: {=+IFERROR(SUM(SUMIF(OFFSET('OCT-21'!$A$1,MATCH(Sheet1!A1,'OCT-21'!$A:$A,0),0,22,1),{"Basic*Arr*","7th Pay* Arr*","DA Arr"},OFFSET('OCT-21'!$A$1,MATCH(Sheet1!A1,'OCT-21'!$A:$A,0),1,22,1))),0)} -> 0 | J12: =SUM(C12:I12) -> 0 | K12: =IFERROR(SUM(SUMIF(OFFSET('OCT-21'!$A$1,MATCH(Sheet1!A1,'OCT-21'!$A:$A,0),2,22,1),{"*Pro*ax*"},OFFSET('OCT-21'!$A$1,MATCH(Sheet1!A1,'OCT-21'!$A:$A,0),3,22,1))),0) -> 0 | L12: {=IFERROR(SUM(SUMIF(OFFSET('OCT-21'!$A$1,MATCH(Sheet1!A1,'OCT-21'!$A:$A,0),2,22,1),{"GPF_G*","DCPS","DCPS DA*"},OFFSET('OCT-21'!$A$1,MATCH(Sheet1!A1,'OCT-21'!$A:$A,0),3,22,1))),0)} -> 0 | M12: =IFERROR(SUM(SUMIF(OFFSET('OCT-21'!$A$1,MATCH(Sheet1!A1,'OCT-21'!$A:$A,0),2,22,1),{"*GIS","GIS*R"},OFFSET('OCT-21'!$A$1,MATCH(Sheet1!A1,'OCT-21'!$A:$A,0),3,22,1))),0) -> 0 | N12: =IFERROR(SUM(SUMIF(OFFSET('OCT-21'!$A$1,MATCH(Sheet1!A1,'OCT-21'!$A:$A,0),5,22,1),{"LI*1"},OFFSET('OCT-21'!$A$1,MATCH(Sheet1!A1,'OCT-21'!$A:$A,0),6,22,1))),0) -> 0 | O12: {=IFERROR(SUM(SUMIF(OFFSET('OCT-21'!$A$1,MATCH(Sheet1!A1,'OCT-21'!$A:$A,0),2,22,1),{"HB*USE","HB*INT"},OFFSET('OCT-21'!$A$1,MATCH(Sheet1!A1,'OCT-21'!$A:$A,0),3,22,1))),0)} -> 0 | P12: {=IFERROR(SUM(SUMIF(OFFSET('OCT-21'!$A$1,MATCH(Sheet1!A1,'OCT-21'!$A:$A,0),5,22,1),{"OTHE*1","CO.*1","OTHE*2","WEL*ND","BAN*1","CLU*ND","RD*1","LI*2","MIS*US","*TAINAN*","MCA*INT*","MAIN*NANCE*","*C M Relief Fund*","Co. Op. Hsg Soc.*","GPF_ADV*","Co. Op. Cr. Soc. 2*","DCPS Pay"},OFFSET('OCT-21'!$A$1,MATCH(Sheet1!A1,'OCT-21'!$A:$A,0),6,22,1)))+SUM(SUMIF(OFFSET('OCT-21'!$A$1,MATCH(Sheet1!A1,'OCT-21'!$A:$A,0),2,22,1),{"MCA","COM*DV*","HB*ND","CO*SOC","HRR","SRV*H","ACC*CY","F.A","STAMP_REVENUE","*C M Relief Fund*","GPF_ADV*","Co. Op. Cr. Soc. 2*","DCPS Pay"},OFFSET('OCT-21'!$A$1,MATCH(Sheet1!A1,'OCT-21'!$A:$A,0),3,22,1))),0)} -> 0 | Q12: =+J12-H12-K12-L12-M12-N12-O12-P12-R12 -> 0 | R12: {=IFERROR(SUM(SUMIF(OFFSET('OCT-21'!$A$1,MATCH(Sheet1!A1,'OCT-21'!$A:$A,0),2,22,1),{"*I. *ax*"},OFFSET('OCT-21'!$A$1,MATCH(Sheet1!A1,'OCT-21'!$A:$A,0),3,22,1))),0)} -> 0 | S12: {=+IFERROR(IF(OFFSET('OCT-21'!$B$1,MATCH(Sheet1!A1,'OCT-21'!B:B,0)-2,0,1,1)=Sheet1!J12,IF(MID(IFERROR(OFFSET('OCT-21'!$B$1,MATCH(Sheet1!A1,'OCT-21'!$B:$B,0)-1,-1,1,1),"GROSS ERROR"),11,FIND(" ",OFFSET('OCT-21'!$B$1,MATCH(Sheet1!A1,'OCT-21'!$B:$B,0)-1,-1,1,1),12)-11)-Q12=0,"","NET MISMATCH"),"GROSS MISMATCH"),"")} | BH12: =+G2 -> PAN | BI12: =+A1 -> 0 | BJ12: {=+IFERROR(OFFSET('OCT-21'!$B$1,MATCH(Sheet1!A1,'OCT-21'!$B:$B,0)+1,0,1,1),"")} | BK12: =+J12 -> 0 | BL12: =+R12 -> 0 | BM12: {=IFERROR(OFFSET('OCT-21'!$A$1,MATCH(Sheet1!A1,'OCT-21'!$A:$A,0)-2,0,1,1),"")}
A13: 9 | B13: 44501 | C13: =IFERROR(SUM(SUMIF(OFFSET('NOV-21'!$A$1,MATCH(Sheet1!A1,'NOV-21'!$A:$A,0),0,22,1),{"BA*C","BASIC??"},OFFSET('NOV-21'!$A$1,MATCH(Sheet1!A1,'NOV-21'!$A:$A,0),1,22,1))),0) -> 0 | D13: =IFERROR(SUM(SUMIF(OFFSET('NOV-21'!$A$1,MATCH(Sheet1!A1,'NOV-21'!$A:$A,0),0,22,1),{"DA*C","D. *"},OFFSET('NOV-21'!$A$1,MATCH(Sheet1!A1,'NOV-21'!$A:$A,0),1,22,1))),0) -> 0 | E13: =IFERROR(SUM(SUMIF(OFFSET('NOV-21'!$A$1,MATCH(Sheet1!A1,'NOV-21'!$A:$A,0),0,22,1),{"H. R. A."},OFFSET('NOV-21'!$A$1,MATCH(Sheet1!A1,'NOV-21'!$A:$A,0),1,22,1))),0) -> 0 | F13: {=IFERROR(SUM(SUMIF(OFFSET('NOV-21'!$A$1,MATCH(Sheet1!A1,'NOV-21'!$A:$A,0),0,22,1),{"SP*AY*","S D A*","O.A.*","CLA (5th Pay)*","REF. Allow*","Trans.Allw.*","LF*","P. O.*","ARM*","Conv.A*","Otr.Allow*","Trans_Arrear*","BMIA*","Incentives*","Fit Allow*","KMA","NON-*","U.*","ME*A","PG*","Per.Tra"},OFFSET('NOV-21'!$A$1,MATCH(Sheet1!A1,'NOV-21'!$A:$A,0),1,22,1))),0)} -> 0 | G13: =IFERROR(SUM(SUMIF(OFFSET('NOV-21'!$A$1,MATCH(Sheet1!A1,'NOV-21'!$A:$A,0),0,22,1),{"WA"},OFFSET('NOV-21'!$A$1,MATCH(Sheet1!A1,'NOV-21'!$A:$A,0),1,22,1))),0) -> 0 | H13: =IFERROR(SUM(SUMIF(OFFSET('NOV-21'!$A$1,MATCH(Sheet1!A1,'NOV-21'!$A:$A,0),0,22,1),{"DCPS","GROSS_ADJUST"},OFFSET('NOV-21'!$A$1,MATCH(Sheet1!A1,'NOV-21'!$A:$A,0),1,22,1))),0) -> 0 | I13: {=+IFERROR(SUM(SUMIF(OFFSET('NOV-21'!$A$1,MATCH(Sheet1!A1,'NOV-21'!$A:$A,0),0,22,1),{"Basic*Arr*","7th Pay* Arr*","DA Arr"},OFFSET('NOV-21'!$A$1,MATCH(Sheet1!A1,'NOV-21'!$A:$A,0),1,22,1))),0)} -> 0 | J13: =SUM(C13:I13) -> 0 | K13: =IFERROR(SUM(SUMIF(OFFSET('NOV-21'!$A$1,MATCH(Sheet1!A1,'NOV-21'!$A:$A,0),2,22,1),{"*Pro*ax*"},OFFSET('NOV-21'!$A$1,MATCH(Sheet1!A1,'NOV-21'!$A:$A,0),3,22,1))),0) -> 0 | L13: =IFERROR(SUM(SUMIF(OFFSET('NOV-21'!$A$1,MATCH(Sheet1!A1,'NOV-21'!$A:$A,0),2,22,1),{"GPF_G*","DCPS"},OFFSET('NOV-21'!$A$1,MATCH(Sheet1!A1,'NOV-21'!$A:$A,0),3,22,1))),0) -> 0 | M13: =IFERROR(SUM(SUMIF(OFFSET('NOV-21'!$A$1,MATCH(Sheet1!A1,'NOV-21'!$A:$A,0),2,22,1),{"*GIS","GIS*R"},OFFSET('NOV-21'!$A$1,MATCH(Sheet1!A1,'NOV-21'!$A:$A,0),3,22,1))),0) -> 0 | N13: =IFERROR(SUM(SUMIF(OFFSET('NOV-21'!$A$1,MATCH(Sheet1!A1,'NOV-21'!$A:$A,0),5,22,1),{"LI*1"},OFFSET('NOV-21'!$A$1,MATCH(Sheet1!A1,'NOV-21'!$A:$A,0),6,22,1))),0) -> 0 | O13: {=IFERROR(SUM(SUMIF(OFFSET('NOV-21'!$A$1,MATCH(Sheet1!A1,'NOV-21'!$A:$A,0),2,22,1),{"HB*USE","HB*INT"},OFFSET('NOV-21'!$A$1,MATCH(Sheet1!A1,'NOV-21'!$A:$A,0),3,22,1))),0)} -> 0 | P13: {=IFERROR(SUM(SUMIF(OFFSET('NOV-21'!$A$1,MATCH(Sheet1!A1,'NOV-21'!$A:$A,0),5,22,1),{"OTHE*1","CO.*1","OTHE*2","WEL*ND","BAN*1","CLU*ND","RD*1","LI*2","MIS*US","*TAINAN*","MCA*INT*","MAIN*NANCE*","*C M Relief Fund*","Co. Op. Hsg Soc.*","GPF_ADV*","Co. Op. Cr. Soc. 2*","DCPS DA","DCPS Pay","MCA Int"},OFFSET('NOV-21'!$A$1,MATCH(Sheet1!A1,'NOV-21'!$A:$A,0),6,22,1)))+SUM(SUMIF(OFFSET('NOV-21'!$A$1,MATCH(Sheet1!A1,'NOV-21'!$A:$A,0),2,22,1),{"MCA","COM*DV*","HB*ND","CO*SOC","HRR","SRV*H","ACC*CY","F.A","STAMP_REVENUE","*C M Relief Fund*","GPF_ADV*","Co. Op. Cr. Soc. 2*","DCPS DA","DCPS Pay","MCA Int"},OFFSET('NOV-21'!$A$1,MATCH(Sheet1!A1,'NOV-21'!$A:$A,0),3,22,1))),0)} -> 0 | Q13: =+J13-H13-K13-L13-M13-N13-O13-P13-R13 -> 0 | R13: {=IFERROR(SUM(SUMIF(OFFSET('NOV-21'!$A$1,MATCH(Sheet1!A1,'NOV-21'!$A:$A,0),2,22,1),{"*I. *ax*"},OFFSET('NOV-21'!$A$1,MATCH(Sheet1!A1,'NOV-21'!$A:$A,0),3,22,1))),0)} -> 0 | S13: {=+IFERROR(IF(OFFSET('NOV-21'!$B$1,MATCH(Sheet1!A1,'NOV-21'!B:B,0)-2,0,1,1)=Sheet1!J13,IF(MID(IFERROR(OFFSET('NOV-21'!$B$1,MATCH(Sheet1!A1,'NOV-21'!$B:$B,0)-1,-1,1,1),"GROSS ERROR"),11,FIND(" ",OFFSET('NOV-21'!$B$1,MATCH(Sheet1!A1,'NOV-21'!$B:$B,0)-1,-1,1,1),12)-11)-Q13=0,"","NET MISMATCH"),"GROSS MISMATCH"),"")} | BH13: =+G2 -> PAN | BI13: =+A1 -> 0 | BJ13: {=+IFERROR(OFFSET('NOV-21'!$B$1,MATCH(Sheet1!A1,'NOV-21'!$B:$B,0)+1,0,1,1),"")} | BK13: =+J13 -> 0 | BL13: =+R13 -> 0 | BM13: {=IFERROR(OFFSET('NOV-21'!$A$1,MATCH(Sheet1!A1,'NOV-21'!$A:$A,0)-2,0,1,1),"")}
A14: 10 | B14: 44531 | C14: =IFERROR(SUM(SUMIF(OFFSET('DEC-21'!$A$1,MATCH(Sheet1!A1,'DEC-21'!$A:$A,0),0,22,1),{"BA*C","BASIC??"},OFFSET('DEC-21'!$A$1,MATCH(Sheet1!A1,'DEC-21'!$A:$A,0),1,22,1))),0) -> 0 | D14: =IFERROR(SUM(SUMIF(OFFSET('DEC-21'!$A$1,MATCH(Sheet1!A1,'DEC-21'!$A:$A,0),0,22,1),{"DA*C","D. *"},OFFSET('DEC-21'!$A$1,MATCH(Sheet1!A1,'DEC-21'!$A:$A,0),1,22,1))),0) -> 0 | E14: =IFERROR(SUM(SUMIF(OFFSET('DEC-21'!$A$1,MATCH(Sheet1!A1,'DEC-21'!$A:$A,0),0,22,1),{"H. R. A."},OFFSET('DEC-21'!$A$1,MATCH(Sheet1!A1,'DEC-21'!$A:$A,0),1,22,1))),0) -> 0 | F14: {=IFERROR(SUM(SUMIF(OFFSET('DEC-21'!$A$1,MATCH(Sheet1!A1,'DEC-21'!$A:$A,0),0,22,1),{"SP*AY*","S D A*","O.A.*","CLA (5th Pay)*","REF. Allow*","Trans.Allw.*","LF*","P. O.*","ARM*","Conv.A*","Otr.Allow*","Trans_Arrear*","BMIA*","Incentives*","Fit Allow*","KMA","NON-*","U.*","ME*A","PG*","Per.Tra"},OFFSET('DEC-21'!$A$1,MATCH(Sheet1!A1,'DEC-21'!$A:$A,0),1,22,1))),0)} -> 0 | G14: =IFERROR(SUM(SUMIF(OFFSET('DEC-21'!$A$1,MATCH(Sheet1!A1,'DEC-21'!$A:$A,0),0,22,1),{"WA"},OFFSET('DEC-21'!$A$1,MATCH(Sheet1!A1,'DEC-21'!$A:$A,0),1,22,1))),0) -> 0 | H14: =IFERROR(SUM(SUMIF(OFFSET('DEC-21'!$A$1,MATCH(Sheet1!A1,'DEC-21'!$A:$A,0),0,22,1),{"DCPS","GROSS_ADJUST"},OFFSET('DEC-21'!$A$1,MATCH(Sheet1!A1,'DEC-21'!$A:$A,0),1,22,1))),0) -> 0 | I14: {=+IFERROR(SUM(SUMIF(OFFSET('DEC-21'!$A$1,MATCH(Sheet1!A1,'DEC-21'!$A:$A,0),0,22,1),{"Basic*Arr*","7th Pay* Arr*"},OFFSET('DEC-21'!$A$1,MATCH(Sheet1!A1,'DEC-21'!$A:$A,0),1,22,1))),0)} -> 0 | J14: =SUM(C14:I14) -> 0 | K14: =IFERROR(SUM(SUMIF(OFFSET('DEC-21'!$A$1,MATCH(Sheet1!A1,'DEC-21'!$A:$A,0),2,22,1),{"*Pro*ax*"},OFFSET('DEC-21'!$A$1,MATCH(Sheet1!A1,'DEC-21'!$A:$A,0),3,22,1))),0) -> 0 | L14: =IFERROR(SUM(SUMIF(OFFSET('DEC-21'!$A$1,MATCH(Sheet1!A1,'DEC-21'!$A:$A,0),2,22,1),{"GPF_G*","DCPS"},OFFSET('DEC-21'!$A$1,MATCH(Sheet1!A1,'DEC-21'!$A:$A,0),3,22,1))),0) -> 0 | M14: =IFERROR(SUM(SUMIF(OFFSET('DEC-21'!$A$1,MATCH(Sheet1!A1,'DEC-21'!$A:$A,0),2,22,1),{"*GIS","GIS*R"},OFFSET('DEC-21'!$A$1,MATCH(Sheet1!A1,'DEC-21'!$A:$A,0),3,22,1))),0) -> 0 | N14: =IFERROR(SUM(SUMIF(OFFSET('DEC-21'!$A$1,MATCH(Sheet1!A1,'DEC-21'!$A:$A,0),5,22,1),{"LI*1"},OFFSET('DEC-21'!$A$1,MATCH(Sheet1!A1,'DEC-21'!$A:$A,0),6,22,1))),0) -> 0 | O14: {=IFERROR(SUM(SUMIF(OFFSET('DEC-21'!$A$1,MATCH(Sheet1!A1,'DEC-21'!$A:$A,0),2,22,1),{"HB*USE","HB*INT"},OFFSET('DEC-21'!$A$1,MATCH(Sheet1!A1,'DEC-21'!$A:$A,0),3,22,1))),0)} -> 0 | P14: {=IFERROR(SUM(SUMIF(OFFSET('DEC-21'!$A$1,MATCH(Sheet1!A1,'DEC-21'!$A:$A,0),5,22,1),{"OTHE*1","CO.*1","OTHE*2","WEL*ND","BAN*1","CLU*ND","RD*1","LI*2","MIS*US","*TAINAN*","MCA*INT*","MAIN*NANCE*","*C M Relief Fund*","Co. Op. Hsg Soc.*","GPF_ADV*","Co. Op. Cr. Soc. 2*","DCPS DA","DCPS Pay","MCA Int"},OFFSET('DEC-21'!$A$1,MATCH(Sheet1!A1,'DEC-21'!$A:$A,0),6,22,1)))+SUM(SUMIF(OFFSET('DEC-21'!$A$1,MATCH(Sheet1!A1,'DEC-21'!$A:$A,0),2,22,1),{"MCA","COM*DV*","HB*ND","CO*SOC","HRR","SRV*H","ACC*CY","F.A","STAMP_REVENUE","*C M Relief Fund*","GPF_ADV*","Co. Op. Cr. Soc. 2*","DCPS DA","DCPS Pay","MCA Int"},OFFSET('DEC-21'!$A$1,MATCH(Sheet1!A1,'DEC-21'!$A:$A,0),3,22,1))),0)} -> 0 | Q14: =+J14-H14-K14-L14-M14-N14-O14-P14-R14 -> 0 | R14: {=IFERROR(SUM(SUMIF(OFFSET('DEC-21'!$A$1,MATCH(Sheet1!A1,'DEC-21'!$A:$A,0),2,22,1),{"*I. *ax*"},OFFSET('DEC-21'!$A$1,MATCH(Sheet1!A1,'DEC-21'!$A:$A,0),3,22,1))),0)} -> 0 | S14: {=+IFERROR(IF(OFFSET('DEC-21'!$B$1,MATCH(Sheet1!A1,'DEC-21'!B:B,0)-2,0,1,1)=Sheet1!J14,IF(MID(IFERROR(OFFSET('DEC-21'!$B$1,MATCH(Sheet1!A1,'DEC-21'!$B:$B,0)-1,-1,1,1),"GROSS ERROR"),11,FIND(" ",OFFSET('DEC-21'!$B$1,MATCH(Sheet1!A1,'DEC-21'!$B:$B,0)-1,-1,1,1),12)-11)-Q14=0,"","NET MISMATCH"),"GROSS MISMATCH"),"")} | BH14: =+G2 -> PAN | BI14: =+A1 -> 0 | BJ14: {=+IFERROR(OFFSET('DEC-21'!$B$1,MATCH(Sheet1!A1,'DEC-21'!$B:$B,0)+1,0,1,1),"")} | BK14: =+J14 -> 0 | BL14: =+R14 -> 0 | BM14: {=IFERROR(OFFSET('DEC-21'!$A$1,MATCH(Sheet1!A1,'DEC-21'!$A:$A,0)-2,0,1,1),"")}
A15: 11 | B15: 44562 | C15: =IFERROR(SUM(SUMIF(OFFSET('JAN-22'!$A$1,MATCH(Sheet1!A1,'JAN-22'!$A:$A,0),0,22,1),{"BA*C","BASIC??"},OFFSET('JAN-22'!$A$1,MATCH(Sheet1!A1,'JAN-22'!$A:$A,0),1,22,1))),0) -> 0 | D15: =IFERROR(SUM(SUMIF(OFFSET('JAN-22'!$A$1,MATCH(Sheet1!A1,'JAN-22'!$A:$A,0),0,22,1),{"DA*C","D. *"},OFFSET('JAN-22'!$A$1,MATCH(Sheet1!A1,'JAN-22'!$A:$A,0),1,22,1))),0) -> 0 | E15: =IFERROR(SUM(SUMIF(OFFSET('JAN-22'!$A$1,MATCH(Sheet1!A1,'JAN-22'!$A:$A,0),0,22,1),{"H. R. A."},OFFSET('JAN-22'!$A$1,MATCH(Sheet1!A1,'JAN-22'!$A:$A,0),1,22,1))),0) -> 0 | F15: {=IFERROR(SUM(SUMIF(OFFSET('JAN-22'!$A$1,MATCH(Sheet1!A1,'JAN-22'!$A:$A,0),0,22,1),{"SP*AY*","S D A*","O.A.*","CLA (5th Pay)*","REF. Allow*","Trans.Allw.*","LF*","P. O.*","ARM*","Conv.A*","Otr.Allow*","Trans_Arrear*","BMIA*","Incentives*","Fit Allow*","KMA","NON-*","U.*","ME*A","PG*","Per.Tra"},OFFSET('JAN-22'!$A$1,MATCH(Sheet1!A1,'JAN-22'!$A:$A,0),1,22,1))),0)} -> 0 | G15: =IFERROR(SUM(SUMIF(OFFSET('JAN-22'!$A$1,MATCH(Sheet1!A1,'JAN-22'!$A:$A,0),0,22,1),{"WA"},OFFSET('JAN-22'!$A$1,MATCH(Sheet1!A1,'JAN-22'!$A:$A,0),1,22,1))),0) -> 0 | H15: =IFERROR(SUM(SUMIF(OFFSET('JAN-22'!$A$1,MATCH(Sheet1!A1,'JAN-22'!$A:$A,0),0,22,1),{"DCPS","GROSS_ADJUST"},OFFSET('JAN-22'!$A$1,MATCH(Sheet1!A1,'JAN-22'!$A:$A,0),1,22,1))),0) -> 0 | I15: {=+IFERROR(SUM(SUMIF(OFFSET('JAN-22'!$A$1,MATCH(Sheet1!A1,'JAN-22'!$A:$A,0),0,22,1),{"Basic*Arr*","7th Pay* Arr*"},OFFSET('JAN-22'!$A$1,MATCH(Sheet1!A1,'JAN-22'!$A:$A,0),1,22,1))),0)} -> 0 | J15: =SUM(C15:I15) -> 0 | K15: =IFERROR(SUM(SUMIF(OFFSET('JAN-22'!$A$1,MATCH(Sheet1!A1,'JAN-22'!$A:$A,0),2,22,1),{"*Pro*ax*"},OFFSET('JAN-22'!$A$1,MATCH(Sheet1!A1,'JAN-22'!$A:$A,0),3,22,1))),0) -> 0 | L15: =IFERROR(SUM(SUMIF(OFFSET('JAN-22'!$A$1,MATCH(Sheet1!A1,'JAN-22'!$A:$A,0),2,22,1),{"GPF_G*","DCPS"},OFFSET('JAN-22'!$A$1,MATCH(Sheet1!A1,'JAN-22'!$A:$A,0),3,22,1))),0) -> 0 | M15: {=IFERROR(SUM(SUMIF(OFFSET('JAN-22'!$A$1,MATCH(Sheet1!A1,'JAN-22'!$A:$A,0),2,22,1),{"*GIS","GIS*R"},OFFSET('JAN-22'!$A$1,MATCH(Sheet1!A1,'JAN-22'!$A:$A,0),3,22,1))),0)} -> 0 | N15: =IFERROR(SUM(SUMIF(OFFSET('JAN-22'!$A$1,MATCH(Sheet1!A1,'JAN-22'!$A:$A,0),5,22,1),{"LI*1"},OFFSET('JAN-22'!$A$1,MATCH(Sheet1!A1,'JAN-22'!$A:$A,0),6,22,1))),0) -> 0 | O15: {=IFERROR(SUM(SUMIF(OFFSET('JAN-22'!$A$1,MATCH(Sheet1!A1,'JAN-22'!$A:$A,0),2,22,1),{"HB*USE","HB*INT"},OFFSET('JAN-22'!$A$1,MATCH(Sheet1!A1,'JAN-22'!$A:$A,0),3,22,1))),0)} -> 0 | P15: {=IFERROR(SUM(SUMIF(OFFSET('JAN-22'!$A$1,MATCH(Sheet1!A1,'JAN-22'!$A:$A,0),5,22,1),{"OTHE*1","CO.*1","OTHE*2","WEL*ND","BAN*1","CLU*ND","RD*1","LI*2","MIS*US","*TAINAN*","MCA*INT*","MAIN*NANCE*","*C M Relief Fund*","Co. Op. Hsg Soc.*","GPF_ADV*","Co. Op. Cr. Soc. 2*","DCPS DA","DCPS Pay","MCA Int"},OFFSET('JAN-22'!$A$1,MATCH(Sheet1!A1,'JAN-22'!$A:$A,0),6,22,1)))+SUM(SUMIF(OFFSET('JAN-22'!$A$1,MATCH(Sheet1!A1,'JAN-22'!$A:$A,0),2,22,1),{"MCA","COM*DV*","HB*ND","CO*SOC","HRR","SRV*H","ACC*CY","F.A","STAMP_REVENUE","*C M Relief Fund*","GPF_ADV*","Co. Op. Cr. Soc. 2*","DCPS DA","DCPS Pay","MCA Int"},OFFSET('JAN-22'!$A$1,MATCH(Sheet1!A1,'JAN-22'!$A:$A,0),3,22,1))),0)} -> 0 | Q15: =+J15-H15-K15-L15-M15-N15-O15-P15-R15 -> 0 | R15: {=IFERROR(SUM(SUMIF(OFFSET('JAN-22'!$A$1,MATCH(Sheet1!A1,'JAN-22'!$A:$A,0),2,22,1),{"*I. *ax*"},OFFSET('JAN-22'!$A$1,MATCH(Sheet1!A1,'JAN-22'!$A:$A,0),3,22,1))),0)} -> 0 | S15: {=+IFERROR(IF(OFFSET('JAN-22'!$B$1,MATCH(Sheet1!A1,'JAN-22'!B:B,0)-2,0,1,1)=Sheet1!J15,IF(MID(IFERROR(OFFSET('JAN-22'!$B$1,MATCH(Sheet1!A1,'JAN-22'!$B:$B,0)-1,-1,1,1),"GROSS ERROR"),11,FIND(" ",OFFSET('JAN-22'!$B$1,MATCH(Sheet1!A1,'JAN-22'!$B:$B,0)-1,-1,1,1),12)-11)-Q15=0,"","NET MISMATCH"),"GROSS MISMATCH"),"")} | BH15: =+G2 -> PAN | BI15: =+A1 -> 0 | BJ15: {=IFERROR(OFFSET('JAN-22'!$B$1,MATCH(Sheet1!A1,'JAN-22'!$B:$B,0)+1,0,1,1),"")} | BK15: =+J15 -> 0 | BL15: =+R15 -> 0 | BM15: {=IFERROR(OFFSET('JAN-22'!$A$1,MATCH(Sheet1!A1,'JAN-22'!$A:$A,0)-2,0,1,1),"")}
A16: 12 | B16: 44593 | C16: =IFERROR(SUM(SUMIF(OFFSET('FEB-22'!$A$1,MATCH(Sheet1!$A$1,'FEB-22'!$A:$A,0),0,22,1),{"BA*C","BASIC??"},OFFSET('FEB-22'!$A$1,MATCH(Sheet1!$A$1,'FEB-22'!$A:$A,0),1,22,1))),0) -> 0 | D16: =IFERROR(SUM(SUMIF(OFFSET('FEB-22'!$A$1,MATCH(Sheet1!$A$1,'FEB-22'!$A:$A,0),0,22,1),{"DA*C","D. *"},OFFSET('FEB-22'!$A$1,MATCH(Sheet1!$A$1,'FEB-22'!$A:$A,0),1,22,1))),0) -> 0 | E16: =IFERROR(SUM(SUMIF(OFFSET('FEB-22'!$A$1,MATCH(Sheet1!$A$1,'FEB-22'!$A:$A,0),0,22,1),{"H. R. A."},OFFSET('FEB-22'!$A$1,MATCH(Sheet1!$A$1,'FEB-22'!$A:$A,0),1,22,1))),0) -> 0 | F16: {=IFERROR(SUM(SUMIF(OFFSET('FEB-22'!$A$1,MATCH(Sheet1!$A$1,'FEB-22'!$A:$A,0),0,22,1),{"SP*AY*","S D A*","O.A.*","CLA (5th Pay)*","REF. Allow*","Trans.Allw.*","LF*","P. O.*","ARM*","Conv.A*","Otr.Allow*","Trans_Arrear*","BMIA*","Incentives*","Fit Allow*","KMA","NON-*","U.*","ME*A","PG*","Per.Tra"},OFFSET('FEB-22'!$A$1,MATCH(Sheet1!$A$1,'FEB-22'!$A:$A,0),1,22,1))),0)} -> 0 | G16: =IFERROR(SUM(SUMIF(OFFSET('FEB-22'!$A$1,MATCH(Sheet1!$A$1,'FEB-22'!$A:$A,0),0,22,1),{"WA"},OFFSET('FEB-22'!$A$1,MATCH(Sheet1!$A$1,'FEB-22'!$A:$A,0),1,22,1))),0) -> 0 | H16: =IFERROR(SUM(SUMIF(OFFSET('FEB-22'!$A$1,MATCH(Sheet1!$A$1,'FEB-22'!$A:$A,0),0,22,1),{"DCPS","GROSS_ADJUST"},OFFSET('FEB-22'!$A$1,MATCH(Sheet1!$A$1,'FEB-22'!$A:$A,0),1,22,1))),0) -> 0 | I16: {=+IFERROR(SUM(SUMIF(OFFSET('FEB-22'!$A$1,MATCH(Sheet1!$A$1,'FEB-22'!$A:$A,0),0,22,1),{"Basic*Arr*","7th Pay* Arr*"},OFFSET('FEB-22'!$A$1,MATCH(Sheet1!$A$1,'FEB-22'!$A:$A,0),1,22,1))),0)} -> 0 | J16: =SUM(C16:I16) -> 0 | K16: =IFERROR(SUM(SUMIF(OFFSET('FEB-22'!$A$1,MATCH(Sheet1!$A$1,'FEB-22'!$A:$A,0),2,22,1),{"*Pro*ax*"},OFFSET('FEB-22'!$A$1,MATCH(Sheet1!$A$1,'FEB-22'!$A:$A,0),3,22,1))),0) -> 0 | L16: =IFERROR(SUM(SUMIF(OFFSET('FEB-22'!$A$1,MATCH(Sheet1!$A$1,'FEB-22'!$A:$A,0),2,22,1),{"GPF_G*","DCPS"},OFFSET('FEB-22'!$A$1,MATCH(Sheet1!$A$1,'FEB-22'!$A:$A,0),3,22,1))),0) -> 0 | M16: {=IFERROR(SUM(SUMIF(OFFSET('FEB-22'!$A$1,MATCH(Sheet1!$A$1,'FEB-22'!$A:$A,0),2,22,1),{"*GIS","GIS*R"},OFFSET('FEB-22'!$A$1,MATCH(Sheet1!$A$1,'FEB-22'!$A:$A,0),3,22,1))),0)} -> 0 | N16: =IFERROR(SUM(SUMIF(OFFSET('FEB-22'!$A$1,MATCH(Sheet1!$A$1,'FEB-22'!$A:$A,0),5,22,1),{"LI*1"},OFFSET('FEB-22'!$A$1,MATCH(Sheet1!$A$1,'FEB-22'!$A:$A,0),6,22,1))),0) -> 0 | O16: {=IFERROR(SUM(SUMIF(OFFSET('FEB-22'!$A$1,MATCH(Sheet1!$A$1,'FEB-22'!$A:$A,0),2,22,1),{"HB*USE","HB*INT"},OFFSET('FEB-22'!$A$1,MATCH(Sheet1!$A$1,'FEB-22'!$A:$A,0),3,22,1))),0)} -> 0 | P16: {=IFERROR(SUM(SUMIF(OFFSET('FEB-22'!$A$1,MATCH(Sheet1!$A$1,'FEB-22'!$A:$A,0),5,22,1),{"OTHE*1","CO.*1","OTHE*2","WEL*ND","BAN*1","CLU*ND","RD*1","LI*2","MIS*US","*TAINAN*","MCA*INT*","MAIN*NANCE*","*C M Relief Fund*","Co. Op. Hsg Soc.*","GPF_ADV*","Co. Op. Cr. Soc. 2*","DCPS DA","DCPS Pay","MCA Int"},OFFSET('FEB-22'!$A$1,MATCH(Sheet1!$A$1,'FEB-22'!$A:$A,0),6,22,1)))+SUM(SUMIF(OFFSET('FEB-22'!$A$1,MATCH(Sheet1!$A$1,'FEB-22'!$A:$A,0),2,22,1),{"MCA","COM*DV*","HB*ND","CO*SOC","HRR","SRV*H","ACC*CY","F.A","STAMP_REVENUE","*C M Relief Fund*","GPF_ADV*","Co. Op. Cr. Soc. 2*","DCPS DA","DCPS Pay","MCA Int"},OFFSET('FEB-22'!$A$1,MATCH(Sheet1!$A$1,'FEB-22'!$A:$A,0),3,22,1))),0)} -> 0 | Q16: =+J16-H16-K16-L16-M16-N16-O16-P16-R16 -> 0 | R16: {=IFERROR(SUM(SUMIF(OFFSET('FEB-22'!$A$1,MATCH(Sheet1!$A$1,'FEB-22'!$A:$A,0),2,22,1),{"*I. *ax*"},OFFSET('FEB-22'!$A$1,MATCH(Sheet1!$A$1,'FEB-22'!$A:$A,0),3,22,1))),0)} -> 0 | S16: {=+IFERROR(IF(OFFSET('FEB-22'!$B$1,MATCH(Sheet1!A1,'FEB-22'!B:B,0)-2,0,1,1)=Sheet1!J16,IF(MID(IFERROR(OFFSET('FEB-22'!$B$1,MATCH(Sheet1!A1,'FEB-22'!$B:$B,0)-1,-1,1,1),"GROSS ERROR"),11,FIND(" ",OFFSET('FEB-22'!$B$1,MATCH(Sheet1!A1,'FEB-22'!$B:$B,0)-1,-1,1,1),12)-11)-Q16=0,"","NET MISMATCH"),"GROSS MISMATCH"),"")} | BH16: =+G2 -> PAN | BI16: =+A1 -> 0 | BJ16: {=IFERROR(OFFSET('FEB-22'!$B$1,MATCH(Sheet1!A1,'FEB-22'!$B:$B,0)+1,0,1,1),"")} | BK16: =+J16 -> 0 | BL16: =+R16 -> 0 | BM16: {=IFERROR(OFFSET('FEB-22'!$A$1,MATCH(Sheet1!A1,'FEB-22'!$A:$A,0)-2,0,1,1),"")}
A17: 13 | B17: SUPP | C17: =IFERROR(SUM(SUMIF(OFFSET(SUPP!$A$1,MATCH(Sheet1!A1,SUPP!$A:$A,0),0,22,1),{"BA*C","BASIC??"},OFFSET(SUPP!$A$1,MATCH(Sheet1!A1,SUPP!$A:$A,0),1,22,1))),0) -> 0 | D17: {=+IFERROR(SUM(SUMIF(OFFSET(SUPP!$A$1,MATCH(Sheet1!A1,SUPP!$A:$A,0),0,22,1),{"DA*C","D. *"},OFFSET(SUPP!$A$1,MATCH(Sheet1!A1,SUPP!$A:$A,0),1,22,1))),0)} -> 0 | E17: =IFERROR(SUM(SUMIF(OFFSET(SUPP!$A$1,MATCH(Sheet1!A1,SUPP!$A:$A,0),0,22,1),{"H. R. A."},OFFSET(SUPP!$A$1,MATCH(Sheet1!A1,SUPP!$A:$A,0),1,22,1))),0) -> 0 | F17: {=IFERROR(SUM(SUMIF(OFFSET(SUPP!$A$1,MATCH(Sheet1!A1,SUPP!$A:$A,0),0,22,1),{"SP*AY*","S D A*","O.A.*","CLA (5th Pay)*","REF. Allow*","Trans.Allw.*","LF*","P. O.*","ARM*","Conv.A*","Otr.Allow*","Trans_Arrear*","BMIA*","Incentives*","Fit Allow*","KMA","NON-*","U.*","ME*A","PG*","Per.Tra"},OFFSET(SUPP!$A$1,MATCH(Sheet1!A1,SUPP!$A:$A,0),1,22,1))),0)} -> 0 | G17: =+IFERROR(SUM(SUMIF(OFFSET(SUPP!$A$1,MATCH(Sheet1!A1,SUPP!$A:$A,0),0,22,1),{"WA"},OFFSET(SUPP!$A$1,MATCH(Sheet1!A1,SUPP!$A:$A,0),1,22,1))),0) -> 0 | H17: {=+IFERROR(SUM(SUMIF(OFFSET(SUPP!$A$1,MATCH(Sheet1!A1,SUPP!$A:$A,0),0,22,1),{"DCPS","GROSS_ADJUST"},OFFSET(SUPP!$A$1,MATCH(Sheet1!A1,SUPP!$A:$A,0),1,22,1))),0)} -> 0 | I17: {=+IFERROR(SUM(SUMIF(OFFSET(SUPP!$A$1,MATCH(Sheet1!A1,SUPP!$A:$A,0),0,22,1),{"Basic*Arr*","7th Pay* Arr*"},OFFSET(SUPP!$A$1,MATCH(Sheet1!A1,SUPP!$A:$A,0),1,22,1))),0)} -> 0 | J17: =SUM(C17:I17) -> 0 | K17: {=+IFERROR(SUM(SUMIF(OFFSET(SUPP!$A$1,MATCH(Sheet1!A1,SUPP!$A:$A,0),2,22,1),{"*Pro*ax*"},OFFSET(SUPP!$A$1,MATCH(Sheet1!A1,SUPP!$A:$A,0),3,22,1))),0)} -> 0 | L17: =IFERROR(SUM(SUMIF(OFFSET(SUPP!$A$1,MATCH(Sheet1!A1,SUPP!$A:$A,0),2,22,1),{"GPF_G*","DCPS"},OFFSET(SUPP!$A$1,MATCH(Sheet1!A1,SUPP!$A:$A,0),3,22,1))),0) -> 0 | M17: {=+IFERROR(SUM(SUMIF(OFFSET(SUPP!$A$1,MATCH(Sheet1!A1,SUPP!$A:$A,0),2,22,1),{"*GIS","GIS*R"},OFFSET(SUPP!$A$1,MATCH(Sheet1!A1,SUPP!$A:$A,0),3,22,1))),0)} -> 0 | N17: {=+IFERROR(SUM(SUMIF(OFFSET(SUPP!$A$1,MATCH(Sheet1!A1,SUPP!$A:$A,0),5,22,1),{"LI*1"},OFFSET(SUPP!$A$1,MATCH(Sheet1!A1,SUPP!$A:$A,0),6,22,1))),0)} -> 0 | O17: {=+IFERROR(SUM(SUMIF(OFFSET(SUPP!$A$1,MATCH(Sheet1!A1,SUPP!$A:$A,0),2,22,1),{"HB*USE","HB*INT"},OFFSET(SUPP!$A$1,MATCH(Sheet1!A1,SUPP!$A:$A,0),3,22,1))),0)} -> 0 | P17: {=IFERROR(SUM(SUMIF(OFFSET(SUPP!$A$1,MATCH(Sheet1!A1,SUPP!$A:$A,0),5,22,1),{"OTHE*1","CO.*1","OTHE*2","WEL*ND","BAN*1","CLU*ND","RD*1","LI*2","MIS*US","*TAINAN*","MCA*INT*","MAIN*NANCE*","*C M Relief Fund*","Co. Op. Hsg Soc.*","GPF_ADV*","Co. Op. Cr. Soc. 2*","DCPS DA","DCPS Pay","MCA Int"},OFFSET(SUPP!$A$1,MATCH(Sheet1!A1,SUPP!$A:$A,0),6,22,1)))+SUM(SUMIF(OFFSET(SUPP!$A$1,MATCH(Sheet1!A1,SUPP!$A:$A,0),2,22,1),{"MCA","COM*DV*","HB*ND","CO*SOC","HRR","SRV*H","ACC*CY","F.A","STAMP_REVENUE","*C M Relief Fund*","GPF_ADV*","Co. Op. Cr. Soc. 2*","DCPS DA","DCPS Pay","MCA Int"},OFFSET(SUPP!$A$1,MATCH(Sheet1!A1,SUPP!$A:$A,0),3,22,1))),0)} -> 0 | Q17: =+J17-H17-K17-L17-M17-N17-O17-P17-R17 -> 0 | R17: {=+IFERROR(SUM(SUMIF(OFFSET(SUPP!$A$1,MATCH(Sheet1!A1,SUPP!$A:$A,0),2,22,1),{"*I. *ax*"},OFFSET(SUPP!$A$1,MATCH(Sheet1!A1,SUPP!$A:$A,0),3,22,1))),0)} -> 0 | S17: {=+IFERROR(IF(OFFSET(SUPP!$B$1,MATCH(Sheet1!A1,SUPP!B:B,0)-2,0,1,1)=Sheet1!J17,IF(MID(IFERROR(OFFSET(SUPP!$B$1,MATCH(Sheet1!A1,SUPP!$B:$B,0)-1,-1,1,1),"GROSS ERROR"),11,FIND(" ",OFFSET(SUPP!$B$1,MATCH(Sheet1!A1,SUPP!$B:$B,0)-1,-1,1,1),12)-11)-Q17=0,"","NET MISMATCH"),"GROSS MISMATCH"),"")} | BH17: =+G2 -> PAN | BI17: =+A1 -> 0 | BJ17: {=IFERROR(OFFSET(SUPP!$B$1,MATCH(Sheet1!A1,SUPP!$B:$B,0)+1,0,1,1),"")} | BK17: =+J17 -> 0 | BL17: =+R17 -> 0 | BM17: =IFERROR(OFFSET(SUPP!$A$1,MATCH(Sheet1!A1,SUPP!$A:$A,0)-2,0,1,1),"")
A18: 14 | B18: MED. BILL | C18: 0 | D18: 0 | E18: 0 | F18: 0 | G18: 0 | H18: 0 | I18: =IFERROR(SUM(SUMIF(OFFSET('AUG-21'!$A$1,MATCH(Sheet1!A9,'AUG-21'!$A:$A,0),0,22,1),{"Arr*","7th Pay* Arr*","Basic Arr."},OFFSET('AUG-21'!$A$1,MATCH(Sheet1!A9,'AUG-21'!$A:$A,0),1,22,1))),0) -> 0 | J18: 0 | K18: 0 | L18: 0 | M18: 0 | N18: 0 | O18: 0 | P18: 0 | Q18: =+J18-H18-K18-L18-M18-N18-O18-P18-P38 -> 0 | R18: 0
N19: 0 | O19: 0 | P19: 0 | Q19: =+J19-H19-K19-L19-M19-N19-O19-P19-P39 -> 0 | R19: 0
B20: TOTAL | C20: =SUM(C5:C19) -> 0 | D20: =SUM(D5:D19) -> 0 | E20: =SUM(E5:E19) -> 0 | F20: =SUM(F5:F19) -> 0 | G20: =SUM(G5:G19) -> 0 | H20: =SUM(H5:H19) -> 0 | I20: =SUM(I5:I19) -> 0 | J20: =SUM(J5:J19) -> 0 | ... R20: =SUM(R5:R19) -> 0
B21: GN
B22: NEW
B24: GROSS SALARY | D24: =+J20 -> 0 | G24: SAVINGS U/S. 80C | K24: Taxable Income | M24: =+D35-H37-H46 -> -50000 | AA24: {=+UPPER(G2)} -> PAN | AB24: =+UPPER(A1) -> 0 | AC24: =+M33-M35 -> 0 | AD24: =+R20 -> 0
B25: LESS : | F25: i) | G25: GPF/DCPS Employee | H25: =+IF(H20>0,L20-H40,L20) -> 0 | K25: Old Tax Regime | M25: =IF(AND(N3="M",M24<=250000),0,IF(AND(N3="F",M24<=250000),0,IF(AND(N3="M",M24<=500000),ROUND((M24-250000)*5%,0),IF(AND(N3="F",M24<=500000),ROUND((M24-250000)*5%,0),IF(AND(N3="M",M24<=1000000),12500+ROUND((M24-500000)*20%,0),IF(AND(N3="F",M24<=1000000),12500+ROUND((M24-500000)*20%,0),IF(AND(N3="M",M24>=1000000),112500+ROUND((M24-1000000)*30%,0),112500+ROUND((M24-1000000)*30%,0)))))))) -> 0
B26: STD. DED. | D26: 50000 | F26: ii) | G26: GIS | H26: =+M20 -> 0 | K26: New Tax Regime | M26: =+IF(AND(B21="GN",(D24-H41)<=250000,B22="OLD"),0,IF(AND(B21="SC",(D24-H41)<=300000,B22="OLD"),0,IF(AND(B21="SSC",(D24-H41)<=500000,B22="OLD"),0,IF(AND(B21="GN",B22="OLD",(D24-H41)<=500000),ROUND(((D24-H41)-250000)*5%,0),IF(AND(B22="OLD",B21="SC",(D24-H41)<=500000),ROUND(((D24-H41)-300000)*5%,0),IF(AND(B22="OLD",(D24-H41)<=1000000,B21="GN"),ROUND(((D24-H41)-500000)*20%+(12500),0),IF(AND(B21="SC",B22="OLD",(D24-H41)<=1000000),ROUND(((D24-H41)-500000)*20%+(10000),0),IF(AND(B21="SSC",B22="OLD",(D24-H41)<=1000000),ROUND(((D24-H41)-500000)*20%,0),IF(AND(B22="OLD",B21="GN",(D24-H41)>1000000),ROUND(((D24-H41)-1000000)*30%+(112500),0),IF(AND(B22="OLD",B21="SC",(D24-H41)>1000000),ROUND(((D24-H41)-1000000)*30%+(110000),0),IF(AND(B21="SSC",B22="OLD",(D24-H41)>1000000),ROUND(((D24-H41)-1000000)*30%+(100000),0),IF(AND(B22="NEW",(D24-H41)<=250000),0,IF(AND(B22="NEW",(D24-H41)<=500000),ROUND(((D24-H41)-250000)*5%,0),IF(AND(B22="NEW",(D24-H41)<=750000),ROUND(((D24-H41)-500000)*10%+(12500),0),IF(AND(B22="NEW",(D24-H41)<=1000000),ROUND(((D24-H41)-750000)*15%+(37500),0),IF(AND(B22="NEW",(D24-H41)<=1250000),ROUND(((D24-H41)-1000000)*20%+(75000),0),IF(AND(B22="NEW",(D24-H41)<=1500000),ROUND(((D24-H41)-1250000)*25%+(125000),0),IF(AND(B22="NEW",(D24-H41)>1500000),ROUND(((D24-H41)-1500000)*30%+(187500),0))))))))))))))))))) -> 0
B27: WA | D27: =+G20 -> 0 | F27: iii) | G27: L.I.C. [Salary] | H27: =+N20 -> 0
B28: Professional Tax | D28: =+K20 -> 0 | F28: iv | G28: L.I.C. [Individual] | H28: 0 | K28: Tax on Total Income | M28: =+IF(M25>M26,M26,M25) -> 0
B29: Other Allowance | D29: 0 | F29: v) | G29: Housing Loan Principal | H29: =+IF(O4="HBA HOUSE",O20,0) -> 0
B30: H. R. A. Exempt | D30: =IF(C42=0,0,MIN(D39:D43)) -> 0 | F30: vi) | G30: Educational Fees | H30: 0 | K30: (-) : Rebate 87 | M30: =IF(M24>500000,0,IF(M28>=12500,12500,M28)) -> 0
B31: B.D.D.S Allowance | D31: 0 | F31: vii) | G31: Mutual Fund | H31: 0 | K31: Tax on Total Inc. | M31: =+M28-M30 -> 0
B32: House Loan Int. | D32: =+IF(O4=B32,O20,0) -> 0 | F32: viii) | G32: PLI | H32: 0 | K32: (+) 4% Edu.Cess | M32: =ROUND(M31*4%,0) -> 0
F33: ix) | G33: Sukanya Yojna | H33: 0 | K33: Tax Payable | M33: =+M31+M32 -> 0
B34: Total Deductions | D34: =SUM(D26:D31)+IF(D32>200000, 200000,D32 ) -> 50000 | F34: x) | G34: PPF | H34: 0 | K34: (-) Already paid | M34: =+R20 -> 0
B35: BALANCE | D35: =+D24-D34 -> -50000 | F35: xI) | G35: SBI Life Insurance | H35: 0 | K35: (-) Relief 89 | M35: 0
G36: Total Savings | H36: =SUM(H25:H35) -> 0
G37: Eligible Savings | H37: =+IF(H36<=150000,H36,150000) -> 0
B38: HRA CALCULATION | K38: Total Tax Payable | M38: =+M33-M34-M35 -> 0
B39: HRA RECEIVED | D39: =+E20 -> 0 | G39: SAVINGS CHAPTER VIA
B40: BASIC + DA 40 % | D40: =+(C20+D20)*40/100 -> 0 | F40: i) | G40: 80CCD (1B) | H40: =+IF(AND(H20>0,L20>50000),50000,IF(H20>0,L20,0)) -> 0
B41: BASIC +DA 10 % | C41: =+(C20+D20)*10/100 -> 0 | F41: ii) | G41: DCPS Employer | H41: =+H20 -> 0
...

Sheet MAR-21
A1: PaySlip

Sheet APR-21
A1: PaySlip

Sheet MAY-21
A1: PaySlip

Sheet JUN-21
A1: PaySlip

Sheet JUL-21
A1: PaySlip

Sheet AUG-21
A1: PaySlip

Sheet SEP-21

Sheet OCT-21

Sheet NOV-21

Sheet DEC-21

Sheet JAN-22

Sheet FEB-22

Sheet SUPP

Sheet EMP NAMES
A1: MONTH | B1: ALL NAMES | C1: ALL PAN | D1: UNIQUE NAMES
A2: 44256 | D2: {=IFERROR(INDEX(B2:B24,MATCH(0,COUNTIF($D$1:D1,B2:B24),0)),"")} -> 0 | E2: =+INDEX($B$2:$C$1500,MATCH(D2,$B$2:$B$1500,0),2) -> #N/A
A3: 44256 | D3: {=IFERROR(INDEX(B3:B25,MATCH(0,COUNTIF($D$1:D2,B3:B25),0)),"")} | E3: =+INDEX($B$2:$C$1500,MATCH(D3,$B$2:$B$1500,0),2) -> #N/A
A4: 44256 | D4: {=IFERROR(INDEX(B4:B26,MATCH(0,COUNTIF($D$1:D3,B4:B26),0)),"")} | E4: =+INDEX($B$2:$C$1500,MATCH(D4,$B$2:$B$1500,0),2) -> #N/A
A5: 44256 | D5: {=IFERROR(INDEX(B5:B27,MATCH(0,COUNTIF($D$1:D4,B5:B27),0)),"")} | E5: =+INDEX($B$2:$C$1500,MATCH(D5,$B$2:$B$1500,0),2) -> #N/A
A6: 44256 | D6: {=IFERROR(INDEX(B6:B28,MATCH(0,COUNTIF($D$1:D5,B6:B28),0)),"")} | E6: =+INDEX($B$2:$C$1500,MATCH(D6,$B$2:$B$1500,0),2) -> #N/A
A7: 44256 | D7: {=IFERROR(INDEX(B7:B29,MATCH(0,COUNTIF($D$1:D6,B7:B29),0)),"")} | E7: =+INDEX($B$2:$C$1500,MATCH(D7,$B$2:$B$1500,0),2) -> #N/A
A8: 44256 | D8: {=IFERROR(INDEX(B8:B30,MATCH(0,COUNTIF($D$1:D7,B8:B30),0)),"")} | E8: =+INDEX($B$2:$C$1500,MATCH(D8,$B$2:$B$1500,0),2) -> #N/A
A9: 44256 | D9: {=IFERROR(INDEX(B9:B31,MATCH(0,COUNTIF($D$1:D8,B9:B31),0)),"")} | E9: =+INDEX($B$2:$C$1500,MATCH(D9,$B$2:$B$1500,0),2) -> #N/A
A10: 44256 | D10: {=IFERROR(INDEX(B10:B32,MATCH(0,COUNTIF($D$1:D9,B10:B32),0)),"")} | E10: =+INDEX($B$2:$C$1500,MATCH(D10,$B$2:$B$1500,0),2) -> #N/A
D11: {=IFERROR(INDEX(B11:B33,MATCH(0,COUNTIF($D$1:D10,B11:B33),0)),"")} | E11: =+INDEX($B$2:$C$1500,MATCH(D11,$B$2:$B$1500,0),2) -> #N/A
D12: {=IFERROR(INDEX(B12:B34,MATCH(0,COUNTIF($D$1:D11,B12:B34),0)),"")} | E12: =+INDEX($B$2:$C$1500,MATCH(D12,$B$2:$B$1500,0),2) -> #N/A
D13: {=IFERROR(INDEX(B13:B35,MATCH(0,COUNTIF($D$1:D12,B13:B35),0)),"")} | E13: =+INDEX($B$2:$C$1500,MATCH(D13,$B$2:$B$1500,0),2) -> #N/A
D14: {=IFERROR(INDEX(B14:B36,MATCH(0,COUNTIF($D$1:D13,B14:B36),0)),"")} | E14: =+INDEX($B$2:$C$1500,MATCH(D14,$B$2:$B$1500,0),2) -> #N/A
D15: {=IFERROR(INDEX(B15:B37,MATCH(0,COUNTIF($D$1:D14,B15:B37),0)),"")} | E15: =+INDEX($B$2:$C$1500,MATCH(D15,$B$2:$B$1500,0),2) -> #N/A
